Workbook

Sheet Satokasvi
B2: Satokasvi
B4: Katetuottolaskelma | G4: Satotason vaihteluun liittyvät valinnat
C5: Määrä | D5: Hinta | E5: Summa | G5: Satotason satunnaisvaihtelu
B6: Tuotot | G6: Keskimääräinen sato | H6: 3500
B7: Ennustettu myyntituotto | C7: =H6 -> 3500 | D7: =H11/1000 -> 0.2 | E7: =C7*D7 -> 700 | G7: Keskimääräinen vaihtelu | H7: 250
B8: Tuet | E8: 500 | G8: Normaalijakauman parametrit (μ, σ) | H8: =H6 -> 3500 | I8: =H7 -> 250
G10: Hintojen satunnaisvaihtelu
G11: Keskimääräinen hinta | H11: 200
B12: Yhteensä | E12: =SUM(E7:E11) -> 1200 | G12: Keskimääräinen vaihtelu | H12: 50
G13: Normaalijakauman parametrit (μ, σ) | H13: =H11 -> 200 | I13: =H12 -> 50
B14: Kustannukset
B15: Siemen | E15: 115 | G15: Sadon epäonnistumisen todennäköisyys | H15: 0.05
B16: Lannoitus | E16: 285
B17: Kasvinsojelu | E17: 37
B18: Muut | E18: 169
B19: Konekustannus | E19: 255
B20: Kiinteät ja työ | E20: 641
B26: Yhteensä | E26: =SUM(E15:E25)-E20 -> 861
B28: Katetuotto | E28: =E12-E26 -> 339

Sheet Toimenpiteet
B2: Maan kasvukunnon parantamiseen tähtäävät toimenpiteet
B5: Kevennetty muokkaus tai suorakylvö
B6: Vaikutus satoon
B7: Välitön vaikutus satoon | C7: -0.2
B8: Pitkäaikainen vaikutus keskisatoon | C8: 0.03
B9: Vaikutus epäonnistumisen todennäköisyyteen | C9: 0
B10: Pitkä aikaväli | C10: 5
C12: Määrä tai muutosprosentti | D12: Hinta | E12: Summa
B13: Tuotot
B18: Yhteensä | E18: =SUM(E5:E17) -> 0
B20: Kustannukset
B21: Työmenekin muutos | C21: -0.66 | D21: 15 | E21: =C21*D21 -> -9.9
B22: Polttoainekustannuksen muutos | C22: -15 | D22: 1.5 | E22: =C22*D22 -> -22.5
B27: Yhteensä | E27: =SUM(E21:E23) -> -32.4
B29: Kustannusvaikutus | E29: =E27 -> -32.4
B32: Alus- ja kerääjäkasvit
B33: Vaikutus satoon
B34: Välitön vaikutus satoon | C34: -0.1
B35: Pitkäaikainen vaikutus keskisatoon | C35: 0.005
B36: Vaikutus epäonnistumisen todennäköisyyteen | C36: 0
B37: Pitkä aikaväli | C37: 5
C39: Määrä tai muutosprosentti | D39: Hinta | E39: Summa
B40: Tuotot
B41: Tuet | E41: 130
B45: Yhteensä | E45: =SUM(E32:E44) -> 130
B47: Kustannukset
B48: Siemenkustannus | E48: 50
B49: Lannoituskustannuksen muutos | C49: -0.3 | E49: =Satokasvi!E16*C49 -> -85.5
B58: Yhteensä | E58: =SUM(E48:E57) -> -35.5
B60: Kustannusvaikutus | E60: =E45-E58 -> 165.5
B63: Lannanlevitys / Orgaaninen lannoite / Maanparannusaine
B64: Vaikutus satoon
B65: Pitkäaikainen vaikutus satotasoon | C65: 0.02
B66: Vaikutus epäonnistumisen todennäköisyyteen | C66: 0
B67: Pitkä aikaväli | C67: 10
C69: Määrä tai muutosprosentti | D69: Hinta | E69: Summa
B70: Tuotot
B71: Lannoituskustannuksen muutos | C71: 0.25 | E71: =C71*Satokasvi!E16 -> 71.25
B72: Tuet | E72: 35
B76: Yhteensä | E76: =SUM(E62:E75) -> 106.25
...

Sheet Simulointi
B2: Katetuottojen simulointi
AC3: Kumulatiiviset sadot (1000 kg) ja katetuotot (€) vuosittain | BD3: Simuloidut katetuotot | BH3: Vaikutuskertoimien vaikutus katetuottoon
B4: Toimenpiteiden ja korkokannan valinta | AD4: Vuosi | BD4: Katetuotto | BE4: Katetuotto yhteensä (ei toimenpiteitä) | BF4: Katetuotto yhteensä (toimenpiteitä tehty) | BH4: Vertailtavat lyhyen aikavälin kertoimet
C5: Vuosi | AD5: 1 | AE5: 2 | AF5: 3 | AG5: 4 | AH5: 5 | AI5: 6 | AJ5: 7 | AK5: 8 | AL5: 9 | AM5: 10 | AN5: 11 | AO5: 12 | AP5: 13 | AQ5: 14 | AR5: 15 | AS5: 16 | AT5: 17 | AU5: 18 | AV5: 19 | AW5: 20 | AX5: 21 | AY5: 22 | AZ5: 23 | BA5: 24 | BB5: 25 | BD5: =BD6-(MAX($HB$62:$HC$161)-MIN($HB$62:$HC$161))/9 -> -735.74488 | BE5: =IF((COUNTIF($HB$62:$HB$161,">="&BD5)-COUNTIF($HB$62:$HB$161,">="&BD6))/100>0,(COUNTIF($HB$62:$HB$161,">="&BD5)-COUNTIF($HB$62:$HB$161,">="&BD6))/100,0) -> 0 | BF5: =IF((COUNTIF($HC$62:$HC$161,">="&BD5)-COUNTIF($HC$62:$HC$161,">="&BD6))/100>0,(COUNTIF($HC$62:$HC$161,">="&BD5)-COUNTIF($HC$62:$HC$161,">="&BD6))/100,0) -> 0 | BH5: Pienin avo | BI5: -0.5
C6: 1 | D6: 2 | E6: 3 | F6: 4 | G6: 5 | H6: 6 | I6: 7 | J6: 8 | K6: 9 | L6: 10 | M6: 11 | N6: 12 | O6: 13 | P6: 14 | Q6: 15 | R6: 16 | S6: 17 | T6: 18 | U6: 19 | V6: 20 | W6: 21 | X6: 22 | Y6: 23 | Z6: 24 | AA6: 25 | AC6: Sato (ei toimenpiteitä) | AD6: =AVERAGE(AB62:AB161)/1000 -> 3.3127776 | AE6: =AVERAGE(AC62:AC161)/1000+AD6 -> 6.6450255 | AF6: =AVERAGE(AD62:AD161)/1000+AE6 -> 9.9868838 | AG6: =AVERAGE(AE62:AE161)/1000+AF6 -> 13.280194 | AH6: =AVERAGE(AF62:AF161)/1000+AG6 -> 16.599205 | AI6: =AVERAGE(AG62:AG161)/1000+AH6 -> 19.975044 | AJ6: =AVERAGE(AH62:AH161)/1000+AI6 -> 23.305871 | AK6: =AVERAGE(AI62:AI161)/1000+AJ6 -> 26.619135 | AL6: =AVERAGE(AJ62:AJ161)/1000+AK6 -> 30.006807 | ... BB6: =AVERAGE(AZ62:AZ161)/1000+BA6 -> 83.250319 | BD6: =MIN($HB$62:$HC$161) -> -256.69627 | BE6: =IF((COUNTIF($HB$62:$HB$161,">="&BD6)-COUNTIF($HB$62:$HB$161,">="&BD7))/100>0,(COUNTIF($HB$62:$HB$161,">="&BD6)-COUNTIF($HB$62:$HB$161,">="&BD7))/100,0) -> 0.01 | BF6: =IF((COUNTIF($HC$62:$HC$161,">="&BD6)-COUNTIF($HC$62:$HC$161,">="&BD7))/100>0,(COUNTIF($HC$62:$HC$161,">="&BD6)-COUNTIF($HC$62:$HC$161,">="&BD7))/100,0) -> 0.01 | BH6: Suurin arvo | BI6: 0.5
B7: Toimenpiteet | AC7: Sato (toimenpiteitä tehty) | AD7: =AVERAGE(BB62:BB161)/1000 -> 2.4018963 | AE7: =AVERAGE(BC62:BC161)/1000+AD7 -> 4.8347038 | AF7: =AVERAGE(BD62:BD161)/1000+AE7 -> 7.2913707 | AG7: =AVERAGE(BE62:BE161)/1000+AF7 -> 9.7289475 | AH7: =AVERAGE(BF62:BF161)/1000+AG7 -> 12.202274 | AI7: =AVERAGE(BG62:BG161)/1000+AH7 -> 14.717949 | AJ7: =AVERAGE(BH62:BH161)/1000+AI7 -> 17.200082 | AK7: =AVERAGE(BI62:BI161)/1000+AJ7 -> 19.669126 | AL7: =AVERAGE(BJ62:BJ161)/1000+AK7 -> 22.193619 | ... BB7: =AVERAGE(BZ62:BZ161)/1000+BA7 -> 61.870685 | BD7: =BD6+(MAX($HB$62:$HC$161)-MIN($HB$62:$HC$161))/9 -> 222.35235 | BE7: =IF((COUNTIF($HB$62:$HB$161,">="&BD7)-COUNTIF($HB$62:$HB$161,">="&BD8))/100>0,(COUNTIF($HB$62:$HB$161,">="&BD7)-COUNTIF($HB$62:$HB$161,">="&BD8))/100,0) -> 0 | BF7: =IF((COUNTIF($HC$62:$HC$161,">="&BD7)-COUNTIF($HC$62:$HC$161,">="&BD8))/100>0,(COUNTIF($HC$62:$HC$161,">="&BD7)-COUNTIF($HC$62:$HC$161,">="&BD8))/100,0) -> 0
B8: Kevennetty muokkaus tai suorakylvö | C8: x | D8: x | E8: x | F8: x | G8: x | H8: x | I8: x | J8: x | K8: x | L8: x | M8: x | N8: x | O8: x | P8: x | Q8: x | R8: x | S8: x | T8: x | U8: x | V8: x | W8: x | X8: x | Y8: x | Z8: x | AA8: x | AC8: Katetuotto (ei toimenpiteitä) | AD8: =AVERAGE(DB62:DB161) -> 331.20343 | AE8: =AVERAGE(DC62:DC161)+AD8 -> 630.30513 | AF8: =AVERAGE(DD62:DD161)+AE8 -> 919.03676 | AG8: =AVERAGE(DE62:DE161)+AF8 -> 1177.6667 | AH8: =AVERAGE(DF62:DF161)+AG8 -> 1426.8183 | AI8: =AVERAGE(DG62:DG161)+AH8 -> 1706.5949 | AJ8: =AVERAGE(DH62:DH161)+AI8 -> 1961.8971 | AK8: =AVERAGE(DI62:DI161)+AJ8 -> 2202.616 | AL8: =AVERAGE(DJ62:DJ161)+AK8 -> 2461.8466 | ... BB8: =AVERAGE(DZ62:DZ161)+BA8 -> 5385.9688 | BD8: =BD7+(MAX($HB$62:$HC$161)-MIN($HB$62:$HC$161))/9 -> 701.40097 | BE8: =IF((COUNTIF($HB$62:$HB$161,">="&BD8)-COUNTIF($HB$62:$HB$161,">="&BD9))/100>0,(COUNTIF($HB$62:$HB$161,">="&BD8)-COUNTIF($HB$62:$HB$161,">="&BD9))/100,0) -> 0 | BF8: =IF((COUNTIF($HC$62:$HC$161,">="&BD8)-COUNTIF($HC$62:$HC$161,">="&BD9))/100>0,(COUNTIF($HC$62:$HC$161,">="&BD8)-COUNTIF($HC$62:$HC$161,">="&BD9))/100,0) -> 0 | BH8: Vertailtavat pitkän aikavälin kertoimet
B9: Alus- ja kerääjäkasvit | C9: x | D9: x | E9: x | F9: x | G9: x | H9: x | I9: x | J9: x | K9: x | L9: x | M9: x | N9: x | O9: x | P9: x | Q9: x | R9: x | S9: x | T9: x | U9: x | V9: x | W9: x | X9: x | Y9: x | Z9: x | AA9: x | AC9: Kkatetuotto (toimenpiteitä tehty) | AD9: =AVERAGE(EB62:EB161) -> 272.98956 | AE9: =AVERAGE(EC62:EC161)+AD9 -> 524.96964 | AF9: =AVERAGE(ED62:ED161)+AE9 -> 771.52001 | AG9: =AVERAGE(EE62:EE161)+AF9 -> 997.8631 | AH9: =AVERAGE(EF62:EF161)+AG9 -> 1218.9989 | AI9: =AVERAGE(EG62:EG161)+AH9 -> 1461.9235 | AJ9: =AVERAGE(EH62:EH161)+AI9 -> 1685.6067 | AK9: =AVERAGE(EI62:EI161)+AJ9 -> 1897.4487 | AL9: =AVERAGE(EJ62:EJ161)+AK9 -> 2122.1403 | ... BB9: =AVERAGE(EZ62:EZ161)+BA9 -> 4697.033 | BD9: =BD8+(MAX($HB$62:$HC$161)-MIN($HB$62:$HC$161))/9 -> 1180.4496 | BE9: =IF((COUNTIF($HB$62:$HB$161,">="&BD9)-COUNTIF($HB$62:$HB$161,">="&BD10))/100>0,(COUNTIF($HB$62:$HB$161,">="&BD9)-COUNTIF($HB$62:$HB$161,">="&BD10))/100,0) -> 0.03 | BF9: =IF((COUNTIF($HC$62:$HC$161,">="&BD9)-COUNTIF($HC$62:$HC$161,">="&BD10))/100>0,(COUNTIF($HC$62:$HC$161,">="&BD9)-COUNTIF($HC$62:$HC$161,">="&BD10))/100,0) -> 0.07 | BH9: Pitkä aikaväli | BI9: 10
B10: Lannanlevitys / Orgaaninen lannoite / Maanparannuskuitu | BD10: =BD9+(MAX($HB$62:$HC$161)-MIN($HB$62:$HC$161))/9 -> 1659.4982 | BE10: =IF((COUNTIF($HB$62:$HB$161,">="&BD10)-COUNTIF($HB$62:$HB$161,">="&BD11))/100>0,(COUNTIF($HB$62:$HB$161,">="&BD10)-COUNTIF($HB$62:$HB$161,">="&BD11))/100,0) -> 0.1 | BF10: =IF((COUNTIF($HC$62:$HC$161,">="&BD10)-COUNTIF($HC$62:$HC$161,">="&BD11))/100>0,(COUNTIF($HC$62:$HC$161,">="&BD10)-COUNTIF($HC$62:$HC$161,">="&BD11))/100,0) -> 0.24 | BH10: Pienin avo | BI10: -0.1
B11: Viherlannoitus / Maanparannus- ja saneerauskasvit | BD11: =BD10+(MAX($HB$62:$HC$161)-MIN($HB$62:$HC$161))/9 -> 2138.5468 | BE11: =IF((COUNTIF($HB$62:$HB$161,">="&BD11)-COUNTIF($HB$62:$HB$161,">="&BD12))/100>0,(COUNTIF($HB$62:$HB$161,">="&BD11)-COUNTIF($HB$62:$HB$161,">="&BD12))/100,0) -> 0.31 | BF11: =IF((COUNTIF($HC$62:$HC$161,">="&BD11)-COUNTIF($HC$62:$HC$161,">="&BD12))/100>0,(COUNTIF($HC$62:$HC$161,">="&BD11)-COUNTIF($HC$62:$HC$161,">="&BD12))/100,0) -> 0.46 | BH11: Suurin arvo | BI11: 0.1
BD12: =BD11+(MAX($HB$62:$HC$161)-MIN($HB$62:$HC$161))/9 -> 2617.5954 | BE12: =IF((COUNTIF($HB$62:$HB$161,">="&BD12)-COUNTIF($HB$62:$HB$161,">="&BD13))/100>0,(COUNTIF($HB$62:$HB$161,">="&BD12)-COUNTIF($HB$62:$HB$161,">="&BD13))/100,0) -> 0.33 | BF12: =IF((COUNTIF($HC$62:$HC$161,">="&BD12)-COUNTIF($HC$62:$HC$161,">="&BD13))/100>0,(COUNTIF($HC$62:$HC$161,">="&BD12)-COUNTIF($HC$62:$HC$161,">="&BD13))/100,0) -> 0.15
B13: Laskentakorko | C13: 0.03 | BD13: =BD12+(MAX($HB$62:$HC$161)-MIN($HB$62:$HC$161))/9 -> 3096.644 | BE13: =IF((COUNTIF($HB$62:$HB$161,">="&BD13)-COUNTIF($HB$62:$HB$161,">="&BD14))/100>0,(COUNTIF($HB$62:$HB$161,">="&BD13)-COUNTIF($HB$62:$HB$161,">="&BD14))/100,0) -> 0.12 | BF13: =IF((COUNTIF($HC$62:$HC$161,">="&BD13)-COUNTIF($HC$62:$HC$161,">="&BD14))/100>0,(COUNTIF($HC$62:$HC$161,">="&BD13)-COUNTIF($HC$62:$HC$161,">="&BD14))/100,0) -> 0.07 | BH13: Tarkastelujakso (vuotta): | BI13: 10
BD14: =BD13+(MAX($HB$62:$HC$161)-MIN($HB$62:$HC$161))/9 -> 3575.6927 | BE14: =IF((COUNTIF($HB$62:$HB$161,">="&BD14)-COUNTIF($HB$62:$HB$161,">="&BD15))/100>0,(COUNTIF($HB$62:$HB$161,">="&BD14)-COUNTIF($HB$62:$HB$161,">="&BD15))/100,0) -> 0.09 | BF14: =IF((COUNTIF($HC$62:$HC$161,">="&BD14)-COUNTIF($HC$62:$HC$161,">="&BD15))/100>0,(COUNTIF($HC$62:$HC$161,">="&BD14)-COUNTIF($HC$62:$HC$161,">="&BD15))/100,0) -> 0
BD15: =MAX($HB$62:$HC$161) -> 4054.7413 | BE15: =IF((COUNTIF($HB$62:$HB$161,">="&BD15)-COUNTIF($HB$62:$HB$161,">="&BD16))/100>0,(COUNTIF($HB$62:$HB$161,">="&BD15)-COUNTIF($HB$62:$HB$161,">="&BD16))/100,0) -> 0.01 | BF15: =IF((COUNTIF($HC$62:$HC$161,">="&BD15)-COUNTIF($HC$62:$HC$161,">="&BD16))/100>0,(COUNTIF($HC$62:$HC$161,">="&BD15)-COUNTIF($HC$62:$HC$161,">="&BD16))/100,0) -> 0 | BH15: Odotettu katetuotto yhteensä (ei toimenpiteitä) | BI15: =_xlfn.XLOOKUP($BI$13,$IG$61:$JE$61,IG62:JE62) -> 2891.7388
BD16: =BD15+(MAX($HB$62:$HC$161)-MIN($HB$62:$HC$161))/9 -> 4533.7899 | BE16: =COUNTIF($HB$62:$HB$161,">"&BD16) -> 0 | BF16: =COUNTIF($HC$62:$HC$161,">"&BD16) -> 0
B17: Pitkän aikavälin vaikutukset | BH17: Odotettu katetuotto yhteensä (toimenpiteitä tehty)
C18: Vuosi | BD18: Tarkastelujakso (vuotta): | BE18: 10 | BJ18: Välitön vaikutus satotasoon
C19: 1 | D19: 2 | E19: 3 | F19: 4 | G19: 5 | H19: 6 | I19: 7 | J19: 8 | K19: 9 | L19: 10 | M19: 11 | N19: 12 | O19: 13 | P19: 14 | Q19: 15 | R19: 16 | S19: 17 | T19: 18 | U19: 19 | V19: 20 | W19: 21 | X19: 22 | Y19: 23 | Z19: 24 | AA19: 25 | BJ19: =HE80 -> -0.5 | BK19: =HE90 -> -0.38888889 | BL19: =HE100 -> -0.27777778 | BM19: =HE110 -> -0.16666667 | BN19: =HE120 -> -0.055555556 | BO19: =HE130 -> 0.055555556 | BP19: =HE140 -> 0.16666667 | BQ19: =HE150 -> 0.27777778 | BR19: =HE160 -> 0.38888889 | BS19: =HE170 -> 0.5
BH20: Pitkäaikainen vaikutus satotasoon | BI20: =HF67 -> -0.1 | BJ20: =_xlfn.XLOOKUP($BI$13,$IG$61:$JE$61,IG183:JE183) -> 884.60129 | BK20: =_xlfn.XLOOKUP($BI$13,$IG$61:$JE$61,IG193:JE193) -> 1513.1867 | BL20: =_xlfn.XLOOKUP($BI$13,$IG$61:$JE$61,IG203:JE203) -> 2141.7722 | BM20: =_xlfn.XLOOKUP($BI$13,$IG$61:$JE$61,IG213:JE213) -> 2770.3576 | BN20: =_xlfn.XLOOKUP($BI$13,$IG$61:$JE$61,IG223:JE223) -> 3398.9431 | BO20: =_xlfn.XLOOKUP($BI$13,$IG$61:$JE$61,IG233:JE233) -> 4027.5285 | BP20: =_xlfn.XLOOKUP($BI$13,$IG$61:$JE$61,IG243:JE243) -> 4656.114 | BQ20: =_xlfn.XLOOKUP($BI$13,$IG$61:$JE$61,IG253:JE253) -> 5284.6994 | BR20: =_xlfn.XLOOKUP($BI$13,$IG$61:$JE$61,IG263:JE263) -> 5913.2849 | BS20: =_xlfn.XLOOKUP($BI$13,$IG$61:$JE$61,IG273:JE273) -> 6541.8703
B21: Vaikutus satoon | BI21: =HF68 -> -0.077777778 | BJ21: =_xlfn.XLOOKUP($BI$13,$IG$61:$JE$61,IG184:JE184) -> 919.47606 | BK21: =_xlfn.XLOOKUP($BI$13,$IG$61:$JE$61,IG194:JE194) -> 1555.8115 | BL21: =_xlfn.XLOOKUP($BI$13,$IG$61:$JE$61,IG204:JE204) -> 2192.1469 | BM21: =_xlfn.XLOOKUP($BI$13,$IG$61:$JE$61,IG214:JE214) -> 2828.4823 | BN21: =_xlfn.XLOOKUP($BI$13,$IG$61:$JE$61,IG224:JE224) -> 3464.8177 | BO21: =_xlfn.XLOOKUP($BI$13,$IG$61:$JE$61,IG234:JE234) -> 4101.1531 | BP21: =_xlfn.XLOOKUP($BI$13,$IG$61:$JE$61,IG244:JE244) -> 4737.4885 | BQ21: =_xlfn.XLOOKUP($BI$13,$IG$61:$JE$61,IG254:JE254) -> 5373.8239 | BR21: =_xlfn.XLOOKUP($BI$13,$IG$61:$JE$61,IG264:JE264) -> 6010.1592 | BS21: =_xlfn.XLOOKUP($BI$13,$IG$61:$JE$61,IG274:JE274) -> 6646.4946
B22: Kevennetty muokkaus tai suorakylvö | C22: =IF(C$19<Toimenpiteet!$C$10,Toimenpiteet!$C$8*100/Toimenpiteet!$C$10*C$19,Toimenpiteet!$C$8*100/Toimenpiteet!$C$10*Toimenpiteet!$C$10) -> 0.6 | D22: =IF(D$19<Toimenpiteet!$C$10,Toimenpiteet!$C$8*100/Toimenpiteet!$C$10*D$19,Toimenpiteet!$C$8*100/Toimenpiteet!$C$10*Toimenpiteet!$C$10) -> 1.2 | E22: =IF(E$19<Toimenpiteet!$C$10,Toimenpiteet!$C$8*100/Toimenpiteet!$C$10*E$19,Toimenpiteet!$C$8*100/Toimenpiteet!$C$10*Toimenpiteet!$C$10) -> 1.8 | F22: =IF(F$19<Toimenpiteet!$C$10,Toimenpiteet!$C$8*100/Toimenpiteet!$C$10*F$19,Toimenpiteet!$C$8*100/Toimenpiteet!$C$10*Toimenpiteet!$C$10) -> 2.4 | G22: =IF(G$19<Toimenpiteet!$C$10,Toimenpiteet!$C$8*100/Toimenpiteet!$C$10*G$19,Toimenpiteet!$C$8*100/Toimenpiteet!$C$10*Toimenpiteet!$C$10) -> 3 | H22: =IF(H$19<Toimenpiteet!$C$10,Toimenpiteet!$C$8*100/Toimenpiteet!$C$10*H$19,Toimenpiteet!$C$8*100/Toimenpiteet!$C$10*Toimenpiteet!$C$10) -> 3 | I22: =IF(I$19<Toimenpiteet!$C$10,Toimenpiteet!$C$8*100/Toimenpiteet!$C$10*I$19,Toimenpiteet!$C$8*100/Toimenpiteet!$C$10*Toimenpiteet!$C$10) -> 3 | J22: =IF(J$19<Toimenpiteet!$C$10,Toimenpiteet!$C$8*100/Toimenpiteet!$C$10*J$19,Toimenpiteet!$C$8*100/Toimenpiteet!$C$10*Toimenpiteet!$C$10) -> 3 | ... AA22: =IF(AA$19<Toimenpiteet!$C$10,Toimenpiteet!$C$8*100/Toimenpiteet!$C$10*AA$19,Toimenpiteet!$C$8*100/Toimenpiteet!$C$10*Toimenpiteet!$C$10) -> 3 | BI22: =HF69 -> -0.055555556 | BJ22: =_xlfn.XLOOKUP($BI$13,$IG$61:$JE$61,IG185:JE185) -> 954.35084 | BK22: =_xlfn.XLOOKUP($BI$13,$IG$61:$JE$61,IG195:JE195) -> 1598.4362 | BL22: =_xlfn.XLOOKUP($BI$13,$IG$61:$JE$61,IG205:JE205) -> 2242.5215 | BM22: =_xlfn.XLOOKUP($BI$13,$IG$61:$JE$61,IG215:JE215) -> 2886.6069 | BN22: =_xlfn.XLOOKUP($BI$13,$IG$61:$JE$61,IG225:JE225) -> 3530.6922 | BO22: =_xlfn.XLOOKUP($BI$13,$IG$61:$JE$61,IG235:JE235) -> 4174.7776 | BP22: =_xlfn.XLOOKUP($BI$13,$IG$61:$JE$61,IG245:JE245) -> 4818.8629 | BQ22: =_xlfn.XLOOKUP($BI$13,$IG$61:$JE$61,IG255:JE255) -> 5462.9483 | BR22: =_xlfn.XLOOKUP($BI$13,$IG$61:$JE$61,IG265:JE265) -> 6107.0336 | BS22: =_xlfn.XLOOKUP($BI$13,$IG$61:$JE$61,IG275:JE275) -> 6751.119
C23: =IF(COUNTIF($C$8:C8,"x")=0,0,_xlfn.XLOOKUP(COUNTIF($C$8:C8,"x"),$C$19:$AA$19,$C$22:$AA$22)) -> 0.6 | D23: =IF(COUNTIF($C$8:D8,"x")=0,0,_xlfn.XLOOKUP(COUNTIF($C$8:D8,"x"),$C$19:$AA$19,$C$22:$AA$22)) -> 1.2 | E23: =IF(COUNTIF($C$8:E8,"x")=0,0,_xlfn.XLOOKUP(COUNTIF($C$8:E8,"x"),$C$19:$AA$19,$C$22:$AA$22)) -> 1.8 | F23: =IF(COUNTIF($C$8:F8,"x")=0,0,_xlfn.XLOOKUP(COUNTIF($C$8:F8,"x"),$C$19:$AA$19,$C$22:$AA$22)) -> 2.4 | G23: =IF(COUNTIF($C$8:G8,"x")=0,0,_xlfn.XLOOKUP(COUNTIF($C$8:G8,"x"),$C$19:$AA$19,$C$22:$AA$22)) -> 3 | H23: =IF(COUNTIF($C$8:H8,"x")=0,0,_xlfn.XLOOKUP(COUNTIF($C$8:H8,"x"),$C$19:$AA$19,$C$22:$AA$22)) -> 3 | I23: =IF(COUNTIF($C$8:I8,"x")=0,0,_xlfn.XLOOKUP(COUNTIF($C$8:I8,"x"),$C$19:$AA$19,$C$22:$AA$22)) -> 3 | J23: =IF(COUNTIF($C$8:J8,"x")=0,0,_xlfn.XLOOKUP(COUNTIF($C$8:J8,"x"),$C$19:$AA$19,$C$22:$AA$22)) -> 3 | ... AA23: =IF(COUNTIF($C$8:AA8,"x")=0,0,_xlfn.XLOOKUP(COUNTIF($C$8:AA8,"x"),$C$19:$AA$19,$C$22:$AA$22)) -> 3 | BI23: =HF70 -> -0.033333333 | BJ23: =_xlfn.XLOOKUP($BI$13,$IG$61:$JE$61,IG186:JE186) -> 989.22561 | BK23: =_xlfn.XLOOKUP($BI$13,$IG$61:$JE$61,IG196:JE196) -> 1641.0609 | BL23: =_xlfn.XLOOKUP($BI$13,$IG$61:$JE$61,IG206:JE206) -> 2292.8962 | BM23: =_xlfn.XLOOKUP($BI$13,$IG$61:$JE$61,IG216:JE216) -> 2944.7315 | BN23: =_xlfn.XLOOKUP($BI$13,$IG$61:$JE$61,IG226:JE226) -> 3596.5668 | BO23: =_xlfn.XLOOKUP($BI$13,$IG$61:$JE$61,IG236:JE236) -> 4248.4021 | BP23: =_xlfn.XLOOKUP($BI$13,$IG$61:$JE$61,IG246:JE246) -> 4900.2374 | BQ23: =_xlfn.XLOOKUP($BI$13,$IG$61:$JE$61,IG256:JE256) -> 5552.0727 | BR23: =_xlfn.XLOOKUP($BI$13,$IG$61:$JE$61,IG266:JE266) -> 6203.908 | BS23: =_xlfn.XLOOKUP($BI$13,$IG$61:$JE$61,IG276:JE276) -> 6855.7433
B24: Alus- ja kerääjäkasvit | C24: =IF(C$19<Toimenpiteet!$C$37,Toimenpiteet!$C$35*100/Toimenpiteet!$C$37*C$19,Toimenpiteet!$C$35*100/Toimenpiteet!$C$37*Toimenpiteet!$C$37) -> 0.1 | D24: =IF(D$19<Toimenpiteet!$C$37,Toimenpiteet!$C$35*100/Toimenpiteet!$C$37*D$19,Toimenpiteet!$C$35*100/Toimenpiteet!$C$37*Toimenpiteet!$C$37) -> 0.2 | E24: =IF(E$19<Toimenpiteet!$C$37,Toimenpiteet!$C$35*100/Toimenpiteet!$C$37*E$19,Toimenpiteet!$C$35*100/Toimenpiteet!$C$37*Toimenpiteet!$C$37) -> 0.3 | F24: =IF(F$19<Toimenpiteet!$C$37,Toimenpiteet!$C$35*100/Toimenpiteet!$C$37*F$19,Toimenpiteet!$C$35*100/Toimenpiteet!$C$37*Toimenpiteet!$C$37) -> 0.4 | G24: =IF(G$19<Toimenpiteet!$C$37,Toimenpiteet!$C$35*100/Toimenpiteet!$C$37*G$19,Toimenpiteet!$C$35*100/Toimenpiteet!$C$37*Toimenpiteet!$C$37) -> 0.5 | H24: =IF(H$19<Toimenpiteet!$C$37,Toimenpiteet!$C$35*100/Toimenpiteet!$C$37*H$19,Toimenpiteet!$C$35*100/Toimenpiteet!$C$37*Toimenpiteet!$C$37) -> 0.5 | I24: =IF(I$19<Toimenpiteet!$C$37,Toimenpiteet!$C$35*100/Toimenpiteet!$C$37*I$19,Toimenpiteet!$C$35*100/Toimenpiteet!$C$37*Toimenpiteet!$C$37) -> 0.5 | J24: =IF(J$19<Toimenpiteet!$C$37,Toimenpiteet!$C$35*100/Toimenpiteet!$C$37*J$19,Toimenpiteet!$C$35*100/Toimenpiteet!$C$37*Toimenpiteet!$C$37) -> 0.5 | ... AA24: =IF(AA$19<Toimenpiteet!$C$37,Toimenpiteet!$C$35*100/Toimenpiteet!$C$37*AA$19,Toimenpiteet!$C$35*100/Toimenpiteet!$C$37*Toimenpiteet!$C$37) -> 0.5 | BI24: =HF71 -> -0.011111111 | BJ24: =_xlfn.XLOOKUP($BI$13,$IG$61:$JE$61,IG187:JE187) -> 1024.1004 | BK24: =_xlfn.XLOOKUP($BI$13,$IG$61:$JE$61,IG197:JE197) -> 1683.6856 | BL24: =_xlfn.XLOOKUP($BI$13,$IG$61:$JE$61,IG207:JE207) -> 2343.2709 | BM24: =_xlfn.XLOOKUP($BI$13,$IG$61:$JE$61,IG217:JE217) -> 3002.8561 | BN24: =_xlfn.XLOOKUP($BI$13,$IG$61:$JE$61,IG227:JE227) -> 3662.4414 | BO24: =_xlfn.XLOOKUP($BI$13,$IG$61:$JE$61,IG237:JE237) -> 4322.0266 | BP24: =_xlfn.XLOOKUP($BI$13,$IG$61:$JE$61,IG247:JE247) -> 4981.6119 | BQ24: =_xlfn.XLOOKUP($BI$13,$IG$61:$JE$61,IG257:JE257) -> 5641.1971 | BR24: =_xlfn.XLOOKUP($BI$13,$IG$61:$JE$61,IG267:JE267) -> 6300.7823 | BS24: =_xlfn.XLOOKUP($BI$13,$IG$61:$JE$61,IG277:JE277) -> 6960.3676
C25: =IF(COUNTIF($C$9:C9,"x")=0,0,_xlfn.XLOOKUP(COUNTIF($C$9:C9,"x"),$C$19:$AA$19,$C$24:$AA$24)) -> 0.1 | D25: =IF(COUNTIF($C$9:D9,"x")=0,0,_xlfn.XLOOKUP(COUNTIF($C$9:D9,"x"),$C$19:$AA$19,$C$24:$AA$24)) -> 0.2 | E25: =IF(COUNTIF($C$9:E9,"x")=0,0,_xlfn.XLOOKUP(COUNTIF($C$9:E9,"x"),$C$19:$AA$19,$C$24:$AA$24)) -> 0.3 | F25: =IF(COUNTIF($C$9:F9,"x")=0,0,_xlfn.XLOOKUP(COUNTIF($C$9:F9,"x"),$C$19:$AA$19,$C$24:$AA$24)) -> 0.4 | G25: =IF(COUNTIF($C$9:G9,"x")=0,0,_xlfn.XLOOKUP(COUNTIF($C$9:G9,"x"),$C$19:$AA$19,$C$24:$AA$24)) -> 0.5 | H25: =IF(COUNTIF($C$9:H9,"x")=0,0,_xlfn.XLOOKUP(COUNTIF($C$9:H9,"x"),$C$19:$AA$19,$C$24:$AA$24)) -> 0.5 | I25: =IF(COUNTIF($C$9:I9,"x")=0,0,_xlfn.XLOOKUP(COUNTIF($C$9:I9,"x"),$C$19:$AA$19,$C$24:$AA$24)) -> 0.5 | J25: =IF(COUNTIF($C$9:J9,"x")=0,0,_xlfn.XLOOKUP(COUNTIF($C$9:J9,"x"),$C$19:$AA$19,$C$24:$AA$24)) -> 0.5 | ... AA25: =IF(COUNTIF($C$9:AA9,"x")=0,0,_xlfn.XLOOKUP(COUNTIF($C$9:AA9,"x"),$C$19:$AA$19,$C$24:$AA$24)) -> 0.5 | BI25: =HF72 -> 0.011111111 | BJ25: =_xlfn.XLOOKUP($BI$13,$IG$61:$JE$61,IG188:JE188) -> 1058.9752 | BK25: =_xlfn.XLOOKUP($BI$13,$IG$61:$JE$61,IG198:JE198) -> 1726.3103 | BL25: =_xlfn.XLOOKUP($BI$13,$IG$61:$JE$61,IG208:JE208) -> 2393.6455 | BM25: =_xlfn.XLOOKUP($BI$13,$IG$61:$JE$61,IG218:JE218) -> 3060.9807 | BN25: =_xlfn.XLOOKUP($BI$13,$IG$61:$JE$61,IG228:JE228) -> 3728.3159 | BO25: =_xlfn.XLOOKUP($BI$13,$IG$61:$JE$61,IG238:JE238) -> 4395.6511 | BP25: =_xlfn.XLOOKUP($BI$13,$IG$61:$JE$61,IG248:JE248) -> 5062.9863 | BQ25: =_xlfn.XLOOKUP($BI$13,$IG$61:$JE$61,IG258:JE258) -> 5730.3215 | BR25: =_xlfn.XLOOKUP($BI$13,$IG$61:$JE$61,IG268:JE268) -> 6397.6567 | BS25: =_xlfn.XLOOKUP($BI$13,$IG$61:$JE$61,IG278:JE278) -> 7064.9919
B26: Lannanlevitys / Orgaaninen lannoite / Maanparannuskuitu | C26: =IF(C$19<Toimenpiteet!$C$67,Toimenpiteet!$C$65*100/Toimenpiteet!$C$67*C$19,Toimenpiteet!$C$65*100/Toimenpiteet!$C$67*Toimenpiteet!$C$67) -> 0.2 | D26: =IF(D$19<Toimenpiteet!$C$67,Toimenpiteet!$C$65*100/Toimenpiteet!$C$67*D$19,Toimenpiteet!$C$65*100/Toimenpiteet!$C$67*Toimenpiteet!$C$67) -> 0.4 | E26: =IF(E$19<Toimenpiteet!$C$67,Toimenpiteet!$C$65*100/Toimenpiteet!$C$67*E$19,Toimenpiteet!$C$65*100/Toimenpiteet!$C$67*Toimenpiteet!$C$67) -> 0.6 | F26: =IF(F$19<Toimenpiteet!$C$67,Toimenpiteet!$C$65*100/Toimenpiteet!$C$67*F$19,Toimenpiteet!$C$65*100/Toimenpiteet!$C$67*Toimenpiteet!$C$67) -> 0.8 | G26: =IF(G$19<Toimenpiteet!$C$67,Toimenpiteet!$C$65*100/Toimenpiteet!$C$67*G$19,Toimenpiteet!$C$65*100/Toimenpiteet!$C$67*Toimenpiteet!$C$67) -> 1 | H26: =IF(H$19<Toimenpiteet!$C$67,Toimenpiteet!$C$65*100/Toimenpiteet!$C$67*H$19,Toimenpiteet!$C$65*100/Toimenpiteet!$C$67*Toimenpiteet!$C$67) -> 1.2 | I26: =IF(I$19<Toimenpiteet!$C$67,Toimenpiteet!$C$65*100/Toimenpiteet!$C$67*I$19,Toimenpiteet!$C$65*100/Toimenpiteet!$C$67*Toimenpiteet!$C$67) -> 1.4 | J26: =IF(J$19<Toimenpiteet!$C$67,Toimenpiteet!$C$65*100/Toimenpiteet!$C$67*J$19,Toimenpiteet!$C$65*100/Toimenpiteet!$C$67*Toimenpiteet!$C$67) -> 1.6 | ... AA26: =IF(AA$19<Toimenpiteet!$C$67,Toimenpiteet!$C$65*100/Toimenpiteet!$C$67*AA$19,Toimenpiteet!$C$65*100/Toimenpiteet!$C$67*Toimenpiteet!$C$67) -> 2 | BI26: =HF73 -> 0.033333333 | BJ26: =_xlfn.XLOOKUP($BI$13,$IG$61:$JE$61,IG189:JE189) -> 1093.8499 | BK26: =_xlfn.XLOOKUP($BI$13,$IG$61:$JE$61,IG199:JE199) -> 1768.9351 | BL26: =_xlfn.XLOOKUP($BI$13,$IG$61:$JE$61,IG209:JE209) -> 2444.0202 | BM26: =_xlfn.XLOOKUP($BI$13,$IG$61:$JE$61,IG219:JE219) -> 3119.1054 | BN26: =_xlfn.XLOOKUP($BI$13,$IG$61:$JE$61,IG229:JE229) -> 3794.1905 | BO26: =_xlfn.XLOOKUP($BI$13,$IG$61:$JE$61,IG239:JE239) -> 4469.2756 | BP26: =_xlfn.XLOOKUP($BI$13,$IG$61:$JE$61,IG249:JE249) -> 5144.3608 | BQ26: =_xlfn.XLOOKUP($BI$13,$IG$61:$JE$61,IG259:JE259) -> 5819.4459 | BR26: =_xlfn.XLOOKUP($BI$13,$IG$61:$JE$61,IG269:JE269) -> 6494.5311 | BS26: =_xlfn.XLOOKUP($BI$13,$IG$61:$JE$61,IG279:JE279) -> 7169.6162
C27: =IF(COUNTIF($C$10:C10,"x")=0,0,_xlfn.XLOOKUP(COUNTIF($C$10:C10,"x"),$C$19:$AA$19,$C$26:$AA$26)) -> 0 | D27: =IF(COUNTIF($C$10:D10,"x")=0,0,_xlfn.XLOOKUP(COUNTIF($C$10:D10,"x"),$C$19:$AA$19,$C$26:$AA$26)) -> 0 | E27: =IF(COUNTIF($C$10:E10,"x")=0,0,_xlfn.XLOOKUP(COUNTIF($C$10:E10,"x"),$C$19:$AA$19,$C$26:$AA$26)) -> 0 | F27: =IF(COUNTIF($C$10:F10,"x")=0,0,_xlfn.XLOOKUP(COUNTIF($C$10:F10,"x"),$C$19:$AA$19,$C$26:$AA$26)) -> 0 | G27: =IF(COUNTIF($C$10:G10,"x")=0,0,_xlfn.XLOOKUP(COUNTIF($C$10:G10,"x"),$C$19:$AA$19,$C$26:$AA$26)) -> 0 | H27: =IF(COUNTIF($C$10:H10,"x")=0,0,_xlfn.XLOOKUP(COUNTIF($C$10:H10,"x"),$C$19:$AA$19,$C$26:$AA$26)) -> 0 | I27: =IF(COUNTIF($C$10:I10,"x")=0,0,_xlfn.XLOOKUP(COUNTIF($C$10:I10,"x"),$C$19:$AA$19,$C$26:$AA$26)) -> 0 | J27: =IF(COUNTIF($C$10:J10,"x")=0,0,_xlfn.XLOOKUP(COUNTIF($C$10:J10,"x"),$C$19:$AA$19,$C$26:$AA$26)) -> 0 | ... AA27: =IF(COUNTIF($C$10:AA10,"x")=0,0,_xlfn.XLOOKUP(COUNTIF($C$10:AA10,"x"),$C$19:$AA$19,$C$26:$AA$26)) -> 0 | BI27: =HF74 -> 0.055555556 | BJ27: =_xlfn.XLOOKUP($BI$13,$IG$61:$JE$61,IG190:JE190) -> 1128.7247 | BK27: =_xlfn.XLOOKUP($BI$13,$IG$61:$JE$61,IG200:JE200) -> 1811.5598 | BL27: =_xlfn.XLOOKUP($BI$13,$IG$61:$JE$61,IG210:JE210) -> 2494.3949 | BM27: =_xlfn.XLOOKUP($BI$13,$IG$61:$JE$61,IG220:JE220) -> 3177.23 | BN27: =_xlfn.XLOOKUP($BI$13,$IG$61:$JE$61,IG230:JE230) -> 3860.0651 | BO27: =_xlfn.XLOOKUP($BI$13,$IG$61:$JE$61,IG240:JE240) -> 4542.9002 | BP27: =_xlfn.XLOOKUP($BI$13,$IG$61:$JE$61,IG250:JE250) -> 5225.7353 | BQ27: =_xlfn.XLOOKUP($BI$13,$IG$61:$JE$61,IG260:JE260) -> 5908.5704 | BR27: =_xlfn.XLOOKUP($BI$13,$IG$61:$JE$61,IG270:JE270) -> 6591.4054 | BS27: =_xlfn.XLOOKUP($BI$13,$IG$61:$JE$61,IG280:JE280) -> 7274.2405
B28: Viherlannoitus | C28: =IF(C$19<Toimenpiteet!$C$95,Toimenpiteet!$C$93*100/Toimenpiteet!$C$95*C$19,Toimenpiteet!$C$93*100/Toimenpiteet!$C$95*Toimenpiteet!$C$95) -> 0.1 | D28: =IF(D$19<Toimenpiteet!$C$95,Toimenpiteet!$C$93*100/Toimenpiteet!$C$95*D$19,Toimenpiteet!$C$93*100/Toimenpiteet!$C$95*Toimenpiteet!$C$95) -> 0.2 | E28: =IF(E$19<Toimenpiteet!$C$95,Toimenpiteet!$C$93*100/Toimenpiteet!$C$95*E$19,Toimenpiteet!$C$93*100/Toimenpiteet!$C$95*Toimenpiteet!$C$95) -> 0.3 | F28: =IF(F$19<Toimenpiteet!$C$95,Toimenpiteet!$C$93*100/Toimenpiteet!$C$95*F$19,Toimenpiteet!$C$93*100/Toimenpiteet!$C$95*Toimenpiteet!$C$95) -> 0.4 | G28: =IF(G$19<Toimenpiteet!$C$95,Toimenpiteet!$C$93*100/Toimenpiteet!$C$95*G$19,Toimenpiteet!$C$93*100/Toimenpiteet!$C$95*Toimenpiteet!$C$95) -> 0.5 | H28: =IF(H$19<Toimenpiteet!$C$95,Toimenpiteet!$C$93*100/Toimenpiteet!$C$95*H$19,Toimenpiteet!$C$93*100/Toimenpiteet!$C$95*Toimenpiteet!$C$95) -> 0.6 | I28: =IF(I$19<Toimenpiteet!$C$95,Toimenpiteet!$C$93*100/Toimenpiteet!$C$95*I$19,Toimenpiteet!$C$93*100/Toimenpiteet!$C$95*Toimenpiteet!$C$95) -> 0.7 | J28: =IF(J$19<Toimenpiteet!$C$95,Toimenpiteet!$C$93*100/Toimenpiteet!$C$95*J$19,Toimenpiteet!$C$93*100/Toimenpiteet!$C$95*Toimenpiteet!$C$95) -> 0.8 | ... AA28: =IF(AA$19<Toimenpiteet!$C$95,Toimenpiteet!$C$93*100/Toimenpiteet!$C$95*AA$19,Toimenpiteet!$C$93*100/Toimenpiteet!$C$95*Toimenpiteet!$C$95) -> 1 | BI28: =HF75 -> 0.077777778 | BJ28: =_xlfn.XLOOKUP($BI$13,$IG$61:$JE$61,IG191:JE191) -> 1163.5995 | BK28: =_xlfn.XLOOKUP($BI$13,$IG$61:$JE$61,IG201:JE201) -> 1854.1845 | BL28: =_xlfn.XLOOKUP($BI$13,$IG$61:$JE$61,IG211:JE211) -> 2544.7696 | BM28: =_xlfn.XLOOKUP($BI$13,$IG$61:$JE$61,IG221:JE221) -> 3235.3546 | BN28: =_xlfn.XLOOKUP($BI$13,$IG$61:$JE$61,IG231:JE231) -> 3925.9396 | BO28: =_xlfn.XLOOKUP($BI$13,$IG$61:$JE$61,IG241:JE241) -> 4616.5247 | BP28: =_xlfn.XLOOKUP($BI$13,$IG$61:$JE$61,IG251:JE251) -> 5307.1097 | BQ28: =_xlfn.XLOOKUP($BI$13,$IG$61:$JE$61,IG261:JE261) -> 5997.6948 | BR28: =_xlfn.XLOOKUP($BI$13,$IG$61:$JE$61,IG271:JE271) -> 6688.2798 | BS28: =_xlfn.XLOOKUP($BI$13,$IG$61:$JE$61,IG281:JE281) -> 7378.8649
C29: =IF(COUNTIF($C$11:C11,"x")=0,0,_xlfn.XLOOKUP(COUNTIF($C$11:C11,"x"),$C$19:$AA$19,$C$28:$AA$28)) -> 0 | D29: =IF(COUNTIF($C$11:D11,"x")=0,0,_xlfn.XLOOKUP(COUNTIF($C$11:D11,"x"),$C$19:$AA$19,$C$28:$AA$28)) -> 0 | E29: =IF(COUNTIF($C$11:E11,"x")=0,0,_xlfn.XLOOKUP(COUNTIF($C$11:E11,"x"),$C$19:$AA$19,$C$28:$AA$28)) -> 0 | F29: =IF(COUNTIF($C$11:F11,"x")=0,0,_xlfn.XLOOKUP(COUNTIF($C$11:F11,"x"),$C$19:$AA$19,$C$28:$AA$28)) -> 0 | G29: =IF(COUNTIF($C$11:G11,"x")=0,0,_xlfn.XLOOKUP(COUNTIF($C$11:G11,"x"),$C$19:$AA$19,$C$28:$AA$28)) -> 0 | H29: =IF(COUNTIF($C$11:H11,"x")=0,0,_xlfn.XLOOKUP(COUNTIF($C$11:H11,"x"),$C$19:$AA$19,$C$28:$AA$28)) -> 0 | I29: =IF(COUNTIF($C$11:I11,"x")=0,0,_xlfn.XLOOKUP(COUNTIF($C$11:I11,"x"),$C$19:$AA$19,$C$28:$AA$28)) -> 0 | J29: =IF(COUNTIF($C$11:J11,"x")=0,0,_xlfn.XLOOKUP(COUNTIF($C$11:J11,"x"),$C$19:$AA$19,$C$28:$AA$28)) -> 0 | ... AA29: =IF(COUNTIF($C$11:AA11,"x")=0,0,_xlfn.XLOOKUP(COUNTIF($C$11:AA11,"x"),$C$19:$AA$19,$C$28:$AA$28)) -> 0 | BI29: =HF76 -> 0.1 | BJ29: =_xlfn.XLOOKUP($BI$13,$IG$61:$JE$61,IG192:JE192) -> 1198.4742 | BK29: =_xlfn.XLOOKUP($BI$13,$IG$61:$JE$61,IG202:JE202) -> 1896.8092 | BL29: =_xlfn.XLOOKUP($BI$13,$IG$61:$JE$61,IG212:JE212) -> 2595.1442 | BM29: =_xlfn.XLOOKUP($BI$13,$IG$61:$JE$61,IG222:JE222) -> 3293.4792 | BN29: =_xlfn.XLOOKUP($BI$13,$IG$61:$JE$61,IG232:JE232) -> 3991.8142 | BO29: =_xlfn.XLOOKUP($BI$13,$IG$61:$JE$61,IG242:JE242) -> 4690.1492 | BP29: =_xlfn.XLOOKUP($BI$13,$IG$61:$JE$61,IG252:JE252) -> 5388.4842 | BQ29: =_xlfn.XLOOKUP($BI$13,$IG$61:$JE$61,IG262:JE262) -> 6086.8192 | BR29: =_xlfn.XLOOKUP($BI$13,$IG$61:$JE$61,IG272:JE272) -> 6785.1542 | BS29: =_xlfn.XLOOKUP($BI$13,$IG$61:$JE$61,IG282:JE282) -> 7483.4892
B30: Kokonaisvaikutus | C30: =SUM(C23+C25+C27+C29)/100 -> 0.007 | D30: =SUM(D23+D25+D27+D29)/100 -> 0.014 | E30: =SUM(E23+E25+E27+E29)/100 -> 0.021 | F30: =SUM(F23+F25+F27+F29)/100 -> 0.028 | G30: =SUM(G23+G25+G27+G29)/100 -> 0.035 | H30: =SUM(H23+H25+H27+H29)/100 -> 0.035 | I30: =SUM(I23+I25+I27+I29)/100 -> 0.035 | J30: =SUM(J23+J25+J27+J29)/100 -> 0.035 | ... AA30: =SUM(AA23+AA25+AA27+AA29)/100 -> 0.035
B32: Vaikutus epäonnistumisen todennäköisyyteen
B33: Kevennetty muokkaus tai suorakylvö | C33: =IF(C$19<Toimenpiteet!$C$10,Toimenpiteet!$C$9*100/Toimenpiteet!$C$10*C$19,Toimenpiteet!$C$9*100/Toimenpiteet!$C$10*Toimenpiteet!$C$10) -> 0 | D33: =IF(D$19<Toimenpiteet!$C$10,Toimenpiteet!$C$9*100/Toimenpiteet!$C$10*D$19,Toimenpiteet!$C$9*100/Toimenpiteet!$C$10*Toimenpiteet!$C$10) -> 0 | E33: =IF(E$19<Toimenpiteet!$C$10,Toimenpiteet!$C$9*100/Toimenpiteet!$C$10*E$19,Toimenpiteet!$C$9*100/Toimenpiteet!$C$10*Toimenpiteet!$C$10) -> 0 | F33: =IF(F$19<Toimenpiteet!$C$10,Toimenpiteet!$C$9*100/Toimenpiteet!$C$10*F$19,Toimenpiteet!$C$9*100/Toimenpiteet!$C$10*Toimenpiteet!$C$10) -> 0 | G33: =IF(G$19<Toimenpiteet!$C$10,Toimenpiteet!$C$9*100/Toimenpiteet!$C$10*G$19,Toimenpiteet!$C$9*100/Toimenpiteet!$C$10*Toimenpiteet!$C$10) -> 0 | H33: =IF(H$19<Toimenpiteet!$C$10,Toimenpiteet!$C$9*100/Toimenpiteet!$C$10*H$19,Toimenpiteet!$C$9*100/Toimenpiteet!$C$10*Toimenpiteet!$C$10) -> 0 | I33: =IF(I$19<Toimenpiteet!$C$10,Toimenpiteet!$C$9*100/Toimenpiteet!$C$10*I$19,Toimenpiteet!$C$9*100/Toimenpiteet!$C$10*Toimenpiteet!$C$10) -> 0 | J33: =IF(J$19<Toimenpiteet!$C$10,Toimenpiteet!$C$9*100/Toimenpiteet!$C$10*J$19,Toimenpiteet!$C$9*100/Toimenpiteet!$C$10*Toimenpiteet!$C$10) -> 0 | ... AA33: =IF(AA$19<Toimenpiteet!$C$10,Toimenpiteet!$C$9*100/Toimenpiteet!$C$10*AA$19,Toimenpiteet!$C$9*100/Toimenpiteet!$C$10*Toimenpiteet!$C$10) -> 0
C34: =IF(COUNTIF($C$8:C8,"x")=0,0,_xlfn.XLOOKUP(COUNTIF($C$8:C8,"x"),$C$19:$AA$19,$C$33:$AA$33)) -> 0 | D34: =IF(COUNTIF($C$8:D8,"x")=0,0,_xlfn.XLOOKUP(COUNTIF($C$8:D8,"x"),$C$19:$AA$19,$C$33:$AA$33)) -> 0 | E34: =IF(COUNTIF($C$8:E8,"x")=0,0,_xlfn.XLOOKUP(COUNTIF($C$8:E8,"x"),$C$19:$AA$19,$C$33:$AA$33)) -> 0 | F34: =IF(COUNTIF($C$8:F8,"x")=0,0,_xlfn.XLOOKUP(COUNTIF($C$8:F8,"x"),$C$19:$AA$19,$C$33:$AA$33)) -> 0 | G34: =IF(COUNTIF($C$8:G8,"x")=0,0,_xlfn.XLOOKUP(COUNTIF($C$8:G8,"x"),$C$19:$AA$19,$C$33:$AA$33)) -> 0 | H34: =IF(COUNTIF($C$8:H8,"x")=0,0,_xlfn.XLOOKUP(COUNTIF($C$8:H8,"x"),$C$19:$AA$19,$C$33:$AA$33)) -> 0 | I34: =IF(COUNTIF($C$8:I8,"x")=0,0,_xlfn.XLOOKUP(COUNTIF($C$8:I8,"x"),$C$19:$AA$19,$C$33:$AA$33)) -> 0 | J34: =IF(COUNTIF($C$8:J8,"x")=0,0,_xlfn.XLOOKUP(COUNTIF($C$8:J8,"x"),$C$19:$AA$19,$C$33:$AA$33)) -> 0 | ... AA34: =IF(COUNTIF($C$8:AA8,"x")=0,0,_xlfn.XLOOKUP(COUNTIF($C$8:AA8,"x"),$C$19:$AA$19,$C$33:$AA$33)) -> 0
B35: Alus- ja kerääjäkasvit | C35: =IF(C$19<Toimenpiteet!$C$37,Toimenpiteet!$C$36*100/Toimenpiteet!$C$37*C$19,Toimenpiteet!$C$36*100/Toimenpiteet!$C$37*Toimenpiteet!$C$37) -> 0 | D35: =IF(D$19<Toimenpiteet!$C$37,Toimenpiteet!$C$36*100/Toimenpiteet!$C$37*D$19,Toimenpiteet!$C$36*100/Toimenpiteet!$C$37*Toimenpiteet!$C$37) -> 0 | E35: =IF(E$19<Toimenpiteet!$C$37,Toimenpiteet!$C$36*100/Toimenpiteet!$C$37*E$19,Toimenpiteet!$C$36*100/Toimenpiteet!$C$37*Toimenpiteet!$C$37) -> 0 | F35: =IF(F$19<Toimenpiteet!$C$37,Toimenpiteet!$C$36*100/Toimenpiteet!$C$37*F$19,Toimenpiteet!$C$36*100/Toimenpiteet!$C$37*Toimenpiteet!$C$37) -> 0 | G35: =IF(G$19<Toimenpiteet!$C$37,Toimenpiteet!$C$36*100/Toimenpiteet!$C$37*G$19,Toimenpiteet!$C$36*100/Toimenpiteet!$C$37*Toimenpiteet!$C$37) -> 0 | H35: =IF(H$19<Toimenpiteet!$C$37,Toimenpiteet!$C$36*100/Toimenpiteet!$C$37*H$19,Toimenpiteet!$C$36*100/Toimenpiteet!$C$37*Toimenpiteet!$C$37) -> 0 | I35: =IF(I$19<Toimenpiteet!$C$37,Toimenpiteet!$C$36*100/Toimenpiteet!$C$37*I$19,Toimenpiteet!$C$36*100/Toimenpiteet!$C$37*Toimenpiteet!$C$37) -> 0 | J35: =IF(J$19<Toimenpiteet!$C$37,Toimenpiteet!$C$36*100/Toimenpiteet!$C$37*J$19,Toimenpiteet!$C$36*100/Toimenpiteet!$C$37*Toimenpiteet!$C$37) -> 0 | ... AA35: =IF(AA$19<Toimenpiteet!$C$37,Toimenpiteet!$C$36*100/Toimenpiteet!$C$37*AA$19,Toimenpiteet!$C$36*100/Toimenpiteet!$C$37*Toimenpiteet!$C$37) -> 0
C36: =IF(COUNTIF($C$9:C9,"x")=0,0,_xlfn.XLOOKUP(COUNTIF($C$9:C9,"x"),$C$19:$AA$19,$C$35:$AA$35)) -> 0 | D36: =IF(COUNTIF($C$9:D9,"x")=0,0,_xlfn.XLOOKUP(COUNTIF($C$9:D9,"x"),$C$19:$AA$19,$C$35:$AA$35)) -> 0 | E36: =IF(COUNTIF($C$9:E9,"x")=0,0,_xlfn.XLOOKUP(COUNTIF($C$9:E9,"x"),$C$19:$AA$19,$C$35:$AA$35)) -> 0 | F36: =IF(COUNTIF($C$9:F9,"x")=0,0,_xlfn.XLOOKUP(COUNTIF($C$9:F9,"x"),$C$19:$AA$19,$C$35:$AA$35)) -> 0 | G36: =IF(COUNTIF($C$9:G9,"x")=0,0,_xlfn.XLOOKUP(COUNTIF($C$9:G9,"x"),$C$19:$AA$19,$C$35:$AA$35)) -> 0 | H36: =IF(COUNTIF($C$9:H9,"x")=0,0,_xlfn.XLOOKUP(COUNTIF($C$9:H9,"x"),$C$19:$AA$19,$C$35:$AA$35)) -> 0 | I36: =IF(COUNTIF($C$9:I9,"x")=0,0,_xlfn.XLOOKUP(COUNTIF($C$9:I9,"x"),$C$19:$AA$19,$C$35:$AA$35)) -> 0 | J36: =IF(COUNTIF($C$9:J9,"x")=0,0,_xlfn.XLOOKUP(COUNTIF($C$9:J9,"x"),$C$19:$AA$19,$C$35:$AA$35)) -> 0 | ... AA36: =IF(COUNTIF($C$9:AA9,"x")=0,0,_xlfn.XLOOKUP(COUNTIF($C$9:AA9,"x"),$C$19:$AA$19,$C$35:$AA$35)) -> 0
B37: Lannanlevitys / Orgaaninen lannoite / Maanparannuskuitu | C37: =IF(C$19<Toimenpiteet!$C$67,Toimenpiteet!$C$66*100/Toimenpiteet!$C$67*C$19,Toimenpiteet!$C$66*100/Toimenpiteet!$C$67*Toimenpiteet!$C$67) -> 0 | D37: =IF(D$19<Toimenpiteet!$C$67,Toimenpiteet!$C$66*100/Toimenpiteet!$C$67*D$19,Toimenpiteet!$C$66*100/Toimenpiteet!$C$67*Toimenpiteet!$C$67) -> 0 | E37: =IF(E$19<Toimenpiteet!$C$67,Toimenpiteet!$C$66*100/Toimenpiteet!$C$67*E$19,Toimenpiteet!$C$66*100/Toimenpiteet!$C$67*Toimenpiteet!$C$67) -> 0 | F37: =IF(F$19<Toimenpiteet!$C$67,Toimenpiteet!$C$66*100/Toimenpiteet!$C$67*F$19,Toimenpiteet!$C$66*100/Toimenpiteet!$C$67*Toimenpiteet!$C$67) -> 0 | G37: =IF(G$19<Toimenpiteet!$C$67,Toimenpiteet!$C$66*100/Toimenpiteet!$C$67*G$19,Toimenpiteet!$C$66*100/Toimenpiteet!$C$67*Toimenpiteet!$C$67) -> 0 | H37: =IF(H$19<Toimenpiteet!$C$67,Toimenpiteet!$C$66*100/Toimenpiteet!$C$67*H$19,Toimenpiteet!$C$66*100/Toimenpiteet!$C$67*Toimenpiteet!$C$67) -> 0 | I37: =IF(I$19<Toimenpiteet!$C$67,Toimenpiteet!$C$66*100/Toimenpiteet!$C$67*I$19,Toimenpiteet!$C$66*100/Toimenpiteet!$C$67*Toimenpiteet!$C$67) -> 0 | J37: =IF(J$19<Toimenpiteet!$C$67,Toimenpiteet!$C$66*100/Toimenpiteet!$C$67*J$19,Toimenpiteet!$C$66*100/Toimenpiteet!$C$67*Toimenpiteet!$C$67) -> 0 | ... AA37: =IF(AA$19<Toimenpiteet!$C$67,Toimenpiteet!$C$66*100/Toimenpiteet!$C$67*AA$19,Toimenpiteet!$C$66*100/Toimenpiteet!$C$67*Toimenpiteet!$C$67) -> 0
C38: =IF(COUNTIF($C$10:C10,"x")=0,0,_xlfn.XLOOKUP(COUNTIF($C$10:C10,"x"),$C$19:$AA$19,$C$33:$AA$33)) -> 0 | D38: =IF(COUNTIF($C$10:D10,"x")=0,0,_xlfn.XLOOKUP(COUNTIF($C$10:D10,"x"),$C$19:$AA$19,$C$33:$AA$33)) -> 0 | E38: =IF(COUNTIF($C$10:E10,"x")=0,0,_xlfn.XLOOKUP(COUNTIF($C$10:E10,"x"),$C$19:$AA$19,$C$33:$AA$33)) -> 0 | F38: =IF(COUNTIF($C$10:F10,"x")=0,0,_xlfn.XLOOKUP(COUNTIF($C$10:F10,"x"),$C$19:$AA$19,$C$33:$AA$33)) -> 0 | G38: =IF(COUNTIF($C$10:G10,"x")=0,0,_xlfn.XLOOKUP(COUNTIF($C$10:G10,"x"),$C$19:$AA$19,$C$33:$AA$33)) -> 0 | H38: =IF(COUNTIF($C$10:H10,"x")=0,0,_xlfn.XLOOKUP(COUNTIF($C$10:H10,"x"),$C$19:$AA$19,$C$33:$AA$33)) -> 0 | I38: =IF(COUNTIF($C$10:I10,"x")=0,0,_xlfn.XLOOKUP(COUNTIF($C$10:I10,"x"),$C$19:$AA$19,$C$33:$AA$33)) -> 0 | J38: =IF(COUNTIF($C$10:J10,"x")=0,0,_xlfn.XLOOKUP(COUNTIF($C$10:J10,"x"),$C$19:$AA$19,$C$33:$AA$33)) -> 0 | ... AA38: =IF(COUNTIF($C$10:AA10,"x")=0,0,_xlfn.XLOOKUP(COUNTIF($C$10:AA10,"x"),$C$19:$AA$19,$C$33:$AA$33)) -> 0
B39: Viherlannoitus | C39: =IF(C$19<Toimenpiteet!$C$95,Toimenpiteet!$C$94*100/Toimenpiteet!$C$95*C$19,Toimenpiteet!$C$94*100/Toimenpiteet!$C$95*Toimenpiteet!$C$95) -> 0 | D39: =IF(D$19<Toimenpiteet!$C$95,Toimenpiteet!$C$94*100/Toimenpiteet!$C$95*D$19,Toimenpiteet!$C$94*100/Toimenpiteet!$C$95*Toimenpiteet!$C$95) -> 0 | E39: =IF(E$19<Toimenpiteet!$C$95,Toimenpiteet!$C$94*100/Toimenpiteet!$C$95*E$19,Toimenpiteet!$C$94*100/Toimenpiteet!$C$95*Toimenpiteet!$C$95) -> 0 | F39: =IF(F$19<Toimenpiteet!$C$95,Toimenpiteet!$C$94*100/Toimenpiteet!$C$95*F$19,Toimenpiteet!$C$94*100/Toimenpiteet!$C$95*Toimenpiteet!$C$95) -> 0 | G39: =IF(G$19<Toimenpiteet!$C$95,Toimenpiteet!$C$94*100/Toimenpiteet!$C$95*G$19,Toimenpiteet!$C$94*100/Toimenpiteet!$C$95*Toimenpiteet!$C$95) -> 0 | H39: =IF(H$19<Toimenpiteet!$C$95,Toimenpiteet!$C$94*100/Toimenpiteet!$C$95*H$19,Toimenpiteet!$C$94*100/Toimenpiteet!$C$95*Toimenpiteet!$C$95) -> 0 | I39: =IF(I$19<Toimenpiteet!$C$95,Toimenpiteet!$C$94*100/Toimenpiteet!$C$95*I$19,Toimenpiteet!$C$94*100/Toimenpiteet!$C$95*Toimenpiteet!$C$95) -> 0 | J39: =IF(J$19<Toimenpiteet!$C$95,Toimenpiteet!$C$94*100/Toimenpiteet!$C$95*J$19,Toimenpiteet!$C$94*100/Toimenpiteet!$C$95*Toimenpiteet!$C$95) -> 0 | ... AA39: =IF(AA$19<Toimenpiteet!$C$95,Toimenpiteet!$C$94*100/Toimenpiteet!$C$95*AA$19,Toimenpiteet!$C$94*100/Toimenpiteet!$C$95*Toimenpiteet!$C$95) -> 0
C40: =IF(COUNTIF($C$11:C11,"x")=0,0,_xlfn.XLOOKUP(COUNTIF($C$11:C11,"x"),$C$19:$AA$19,$C$33:$AA$33)) -> 0 | D40: =IF(COUNTIF($C$11:D11,"x")=0,0,_xlfn.XLOOKUP(COUNTIF($C$11:D11,"x"),$C$19:$AA$19,$C$33:$AA$33)) -> 0 | E40: =IF(COUNTIF($C$11:E11,"x")=0,0,_xlfn.XLOOKUP(COUNTIF($C$11:E11,"x"),$C$19:$AA$19,$C$33:$AA$33)) -> 0 | F40: =IF(COUNTIF($C$11:F11,"x")=0,0,_xlfn.XLOOKUP(COUNTIF($C$11:F11,"x"),$C$19:$AA$19,$C$33:$AA$33)) -> 0 | G40: =IF(COUNTIF($C$11:G11,"x")=0,0,_xlfn.XLOOKUP(COUNTIF($C$11:G11,"x"),$C$19:$AA$19,$C$33:$AA$33)) -> 0 | H40: =IF(COUNTIF($C$11:H11,"x")=0,0,_xlfn.XLOOKUP(COUNTIF($C$11:H11,"x"),$C$19:$AA$19,$C$33:$AA$33)) -> 0 | I40: =IF(COUNTIF($C$11:I11,"x")=0,0,_xlfn.XLOOKUP(COUNTIF($C$11:I11,"x"),$C$19:$AA$19,$C$33:$AA$33)) -> 0 | J40: =IF(COUNTIF($C$11:J11,"x")=0,0,_xlfn.XLOOKUP(COUNTIF($C$11:J11,"x"),$C$19:$AA$19,$C$33:$AA$33)) -> 0 | ... AA40: =IF(COUNTIF($C$11:AA11,"x")=0,0,_xlfn.XLOOKUP(COUNTIF($C$11:AA11,"x"),$C$19:$AA$19,$C$33:$AA$33)) -> 0
B41: Kokonaisvaikutus | C41: =IF(SUM(C34+C36+C38+C40)<=-100,-0.99,IF(SUM(C34+C36+C38+C40)>=100,0.99,SUM(C34+C36+C38+C40)/100)) -> 0 | D41: =IF(SUM(D34+D36+D38+D40)<=-100,-0.99,IF(SUM(D34+D36+D38+D40)>=100,0.99,SUM(D34+D36+D38+D40)/100)) -> 0 | E41: =IF(SUM(E34+E36+E38+E40)<=-100,-0.99,IF(SUM(E34+E36+E38+E40)>=100,0.99,SUM(E34+E36+E38+E40)/100)) -> 0 | F41: =IF(SUM(F34+F36+F38+F40)<=-100,-0.99,IF(SUM(F34+F36+F38+F40)>=100,0.99,SUM(F34+F36+F38+F40)/100)) -> 0 | G41: =IF(SUM(G34+G36+G38+G40)<=-100,-0.99,IF(SUM(G34+G36+G38+G40)>=100,0.99,SUM(G34+G36+G38+G40)/100)) -> 0 | H41: =IF(SUM(H34+H36+H38+H40)<=-100,-0.99,IF(SUM(H34+H36+H38+H40)>=100,0.99,SUM(H34+H36+H38+H40)/100)) -> 0 | I41: =IF(SUM(I34+I36+I38+I40)<=-100,-0.99,IF(SUM(I34+I36+I38+I40)>=100,0.99,SUM(I34+I36+I38+I40)/100)) -> 0 | J41: =IF(SUM(J34+J36+J38+J40)<=-100,-0.99,IF(SUM(J34+J36+J38+J40)>=100,0.99,SUM(J34+J36+J38+J40)/100)) -> 0 | ... AA41: =IF(SUM(AA34+AA36+AA38+AA40)<=-100,-0.99,IF(SUM(AA34+AA36+AA38+AA40)>=100,0.99,SUM(AA34+AA36+AA38+AA40)/100)) -> 0
B57: Simulointitaulukot
...

Sheet Investoinnit
B2: Investoinnit
B4: Jankkurointi | G4: Toimenpiteiden ja korkokannan valinta | AH4: Yhteenvetotaulukko
B5: Vaikutus satoon | H5: Vuosi | AI5: Vuosi
B6: Vaikutus satoon | C6: 0.05 | H6: 1 | I6: 2 | J6: 3 | K6: 4 | L6: 5 | M6: 6 | N6: 7 | O6: 8 | P6: 9 | Q6: 10 | R6: 11 | S6: 12 | T6: 13 | U6: 14 | V6: 15 | W6: 16 | X6: 17 | Y6: 18 | Z6: 19 | AA6: 20 | AB6: 21 | AC6: 22 | AD6: 23 | AE6: 24 | AF6: 25 | AI6: 1 | AJ6: 2 | AK6: 3 | AL6: 4 | AM6: 5 | AN6: 6 | AO6: 7 | AP6: 8 | AQ6: 9 | AR6: 10 | AS6: 11 | AT6: 12 | AU6: 13 | AV6: 14 | AW6: 15 | AX6: 16 | AY6: 17 | AZ6: 18 | BA6: 19 | BB6: 20 | BC6: 21 | BD6: 22 | BE6: 23 | BF6: 24 | BG6: 25
B7: Vaikutus epäonnistumisen todennäköisyyteen | C7: -0.05 | G7: Toimenpiteet ja investoinnit | AH7: Kumulatiivinen katetuotto (ei investointia) | AI7: =AVERAGE(DD60:DD158) -> 305.82524 | AJ7: =AVERAGE(DE60:DE158)+AI7 -> 564.49683 | AK7: =AVERAGE(DF60:DF158)+AJ7 -> 802.58596 | AL7: =AVERAGE(DG60:DG158)+AK7 -> 1062.1941 | AM7: =AVERAGE(DH60:DH158)+AL7 -> 1316.3359 | AN7: =AVERAGE(DI60:DI158)+AM7 -> 1580.1435 | AO7: =AVERAGE(DJ60:DJ158)+AN7 -> 1797.9804 | AP7: =AVERAGE(DK60:DK158)+AO7 -> 2001.0213 | AQ7: =AVERAGE(DL60:DL158)+AP7 -> 2215.8652 | ... BG7: =AVERAGE(EB60:EB158)+BF7 -> 4873.0161
G8: Kevennetty muokkaus tai suorakylvö | I8: x | J8: x | K8: x | L8: x | N8: x | O8: x | P8: x | Q8: x | R8: x | S8: x | T8: x | U8: x | V8: x | W8: x | X8: x | Y8: x | Z8: x | AA8: x | AB8: x | AC8: x | AD8: x | AE8: x | AF8: x | AH8: Kumulatiivinen katetuotto (investointi tehty) | AI8: =AVERAGE(ED60:ED158) -> 305.82524 | AJ8: =AVERAGE(EE60:EE158)+AI8 -> 588.17129 | AK8: =AVERAGE(EF60:EF158)+AJ8 -> 848.59292 | AL8: =AVERAGE(EG60:EG158)+AK8 -> 1131.3058 | AM8: =AVERAGE(EH60:EH158)+AL8 -> 1407.9841 | AN8: =AVERAGE(EI60:EI158)+AM8 -> 1671.7917 | AO8: =AVERAGE(EJ60:EJ158)+AN8 -> 1909.7856 | AP8: =AVERAGE(EK60:EK158)+AO8 -> 2131.9739 | AQ8: =AVERAGE(EL60:EL158)+AP8 -> 2366.2933 | ... BG8: =AVERAGE(FB60:FB158)+BF8 -> 5286.0962
C9: Määrä tai muutosprosentti | D9: Hinta | E9: Summa | G9: Alus- ja kerääjäkasvit | I9: x | J9: x | K9: x | L9: x | N9: x | O9: x | P9: x | Q9: x | R9: x | S9: x | T9: x | U9: x | V9: x | W9: x | X9: x | Y9: x | Z9: x | AA9: x | AB9: x | AC9: x | AD9: x | AE9: x | AF9: x | AH9: Investointikustannus | AI9: =IF(H$12="x",$E$25,0)+IF(H$13="x",$E$51,0) -> 85 | AJ9: =IF(I$12="x",$E$25,0)+IF(I$13="x",$E$51,0) -> 0 | AK9: =IF(J$12="x",$E$25,0)+IF(J$13="x",$E$51,0) -> 0 | AL9: =IF(K$12="x",$E$25,0)+IF(K$13="x",$E$51,0) -> 0 | AM9: =IF(L$12="x",$E$25,0)+IF(L$13="x",$E$51,0) -> 0 | AN9: =IF(M$12="x",$E$25,0)+IF(M$13="x",$E$51,0) -> 85 | AO9: =IF(N$12="x",$E$25,0)+IF(N$13="x",$E$51,0) -> 0 | AP9: =IF(O$12="x",$E$25,0)+IF(O$13="x",$E$51,0) -> 0 | ... BG9: =IF(AF$12="x",$E$25,0)+IF(AF$13="x",$E$51,0) -> 0
B10: Tuotot | G10: Lannanlevitys / Orgaaninen lannoite / Maanparannuskuitu | AH10: Investoinnin kannattavuus | AI10: =AI8-AI7-AI9 -> -85 | AJ10: =AI10+(AJ8-AI8)-(AJ7-AI7)-AJ9 -> -61.32554 | AK10: =AJ10+(AK8-AJ8)-(AK7-AJ7)-AK9 -> -38.993044 | AL10: =AK10+(AL8-AK8)-(AL7-AK7)-AL9 -> -15.888329 | AM10: =AL10+(AM8-AL8)-(AM7-AL7)-AM9 -> 6.6481911 | AN10: =AM10+(AN8-AM8)-(AN7-AM7)-AN9 -> -78.351809 | AO10: =AN10+(AO8-AN8)-(AO7-AN7)-AO9 -> -58.194786 | AP10: =AO10+(AP8-AO8)-(AP7-AO7)-AP9 -> -39.047422 | AQ10: =AP10+(AQ8-AP8)-(AQ7-AP7)-AQ9 -> -19.571909 | ... BG10: =BF10+(BG8-BF8)-(BG7-BF7)-BG9 -> 243.08004
G11: Viherlannoitus / Maanparannus- ja saneerauskasvit | H11: x | M11: x
G12: Jankkurointi | H12: x | M12: x | AH12: Investointi kannattaa (%:n todennäköisyydellä) | AI12: =COUNTIF(HE60:HE159,">0")/COUNT(HE60:HE159) -> 0 | AJ12: =COUNTIF(HF60:HF159,">0")/COUNT(HF60:HF159) -> 0 | AK12: =COUNTIF(HG60:HG159,">0")/COUNT(HG60:HG159) -> 0 | AL12: =COUNTIF(HH60:HH159,">0")/COUNT(HH60:HH159) -> 0.1 | AM12: =COUNTIF(HI60:HI159,">0")/COUNT(HI60:HI159) -> 0.89 | AN12: =COUNTIF(HJ60:HJ159,">0")/COUNT(HJ60:HJ159) -> 1 | AO12: =COUNTIF(HK60:HK159,">0")/COUNT(HK60:HK159) -> 1 | AP12: =COUNTIF(HL60:HL159,">0")/COUNT(HL60:HL159) -> 1 | ... BG12: =COUNTIF(IC60:IC159,">0")/COUNT(IC60:IC159) -> 1
G13: Ojitus
B14: Yhteensä | E14: =SUM(E4:E13) -> 0
G15: Laskentakorko | H15: 0.03
B16: Kustannukset
B17: Urakointihinta | E17: 85
G18: Pitkän aikavälin vaikutukset
H19: Vuosi
H20: 1 | I20: 2 | J20: 3 | K20: 4 | L20: 5 | M20: 6 | N20: 7 | O20: 8 | P20: 9 | Q20: 10 | R20: 11 | S20: 12 | T20: 13 | U20: 14 | V20: 15 | W20: 16 | X20: 17 | Y20: 18 | Z20: 19 | AA20: 20 | AB20: 21 | AC20: 22 | AD20: 23 | AE20: 24 | AF20: 25
G21: Vaikutus satoon
G22: Kevennetty muokkaus tai suorakylvö | H22: =IF(H$20<Toimenpiteet!$C$10,Toimenpiteet!$C$8*100/Toimenpiteet!$C$10*H$20,Toimenpiteet!$C$8*100/Toimenpiteet!$C$10*Toimenpiteet!$C$10) -> 0.6 | I22: =IF(I$20<Toimenpiteet!$C$10,Toimenpiteet!$C$8*100/Toimenpiteet!$C$10*I$20,Toimenpiteet!$C$8*100/Toimenpiteet!$C$10*Toimenpiteet!$C$10) -> 1.2 | J22: =IF(J$20<Toimenpiteet!$C$10,Toimenpiteet!$C$8*100/Toimenpiteet!$C$10*J$20,Toimenpiteet!$C$8*100/Toimenpiteet!$C$10*Toimenpiteet!$C$10) -> 1.8 | K22: =IF(K$20<Toimenpiteet!$C$10,Toimenpiteet!$C$8*100/Toimenpiteet!$C$10*K$20,Toimenpiteet!$C$8*100/Toimenpiteet!$C$10*Toimenpiteet!$C$10) -> 2.4 | L22: =IF(L$20<Toimenpiteet!$C$10,Toimenpiteet!$C$8*100/Toimenpiteet!$C$10*L$20,Toimenpiteet!$C$8*100/Toimenpiteet!$C$10*Toimenpiteet!$C$10) -> 3 | M22: =IF(M$20<Toimenpiteet!$C$10,Toimenpiteet!$C$8*100/Toimenpiteet!$C$10*M$20,Toimenpiteet!$C$8*100/Toimenpiteet!$C$10*Toimenpiteet!$C$10) -> 3 | N22: =IF(N$20<Toimenpiteet!$C$10,Toimenpiteet!$C$8*100/Toimenpiteet!$C$10*N$20,Toimenpiteet!$C$8*100/Toimenpiteet!$C$10*Toimenpiteet!$C$10) -> 3 | O22: =IF(O$20<Toimenpiteet!$C$10,Toimenpiteet!$C$8*100/Toimenpiteet!$C$10*O$20,Toimenpiteet!$C$8*100/Toimenpiteet!$C$10*Toimenpiteet!$C$10) -> 3 | ... AF22: =IF(AF$20<Toimenpiteet!$C$10,Toimenpiteet!$C$8*100/Toimenpiteet!$C$10*AF$20,Toimenpiteet!$C$8*100/Toimenpiteet!$C$10*Toimenpiteet!$C$10) -> 3
B23: Yhteensä | E23: =SUM(E17:E22) -> 85 | H23: =IF(COUNTIF($H$8:H8,"x")=0,0,_xlfn.XLOOKUP(COUNTIF($H$8:H8,"x"),$H$20:$AF$20,$H$22:$AF$22)) -> 0 | I23: =IF(COUNTIF($H$8:I8,"x")=0,0,_xlfn.XLOOKUP(COUNTIF($H$8:I8,"x"),$H$20:$AF$20,$H$22:$AF$22)) -> 0.6 | J23: =IF(COUNTIF($H$8:J8,"x")=0,0,_xlfn.XLOOKUP(COUNTIF($H$8:J8,"x"),$H$20:$AF$20,$H$22:$AF$22)) -> 1.2 | K23: =IF(COUNTIF($H$8:K8,"x")=0,0,_xlfn.XLOOKUP(COUNTIF($H$8:K8,"x"),$H$20:$AF$20,$H$22:$AF$22)) -> 1.8 | L23: =IF(COUNTIF($H$8:L8,"x")=0,0,_xlfn.XLOOKUP(COUNTIF($H$8:L8,"x"),$H$20:$AF$20,$H$22:$AF$22)) -> 2.4 | M23: =IF(COUNTIF($H$8:M8,"x")=0,0,_xlfn.XLOOKUP(COUNTIF($H$8:M8,"x"),$H$20:$AF$20,$H$22:$AF$22)) -> 2.4 | N23: =IF(COUNTIF($H$8:N8,"x")=0,0,_xlfn.XLOOKUP(COUNTIF($H$8:N8,"x"),$H$20:$AF$20,$H$22:$AF$22)) -> 3 | O23: =IF(COUNTIF($H$8:O8,"x")=0,0,_xlfn.XLOOKUP(COUNTIF($H$8:O8,"x"),$H$20:$AF$20,$H$22:$AF$22)) -> 3 | ... AF23: =IF(COUNTIF($H$8:AF8,"x")=0,0,_xlfn.XLOOKUP(COUNTIF($H$8:AF8,"x"),$H$20:$AF$20,$H$22:$AF$22)) -> 3
G24: Alus- ja kerääjäkasvit | H24: =IF(H$20<Toimenpiteet!$C$37,Toimenpiteet!$C$35*100/Toimenpiteet!$C$37*H$20,Toimenpiteet!$C$35*100/Toimenpiteet!$C$37*Toimenpiteet!$C$37) -> 0.1 | I24: =IF(I$20<Toimenpiteet!$C$37,Toimenpiteet!$C$35*100/Toimenpiteet!$C$37*I$20,Toimenpiteet!$C$35*100/Toimenpiteet!$C$37*Toimenpiteet!$C$37) -> 0.2 | J24: =IF(J$20<Toimenpiteet!$C$37,Toimenpiteet!$C$35*100/Toimenpiteet!$C$37*J$20,Toimenpiteet!$C$35*100/Toimenpiteet!$C$37*Toimenpiteet!$C$37) -> 0.3 | K24: =IF(K$20<Toimenpiteet!$C$37,Toimenpiteet!$C$35*100/Toimenpiteet!$C$37*K$20,Toimenpiteet!$C$35*100/Toimenpiteet!$C$37*Toimenpiteet!$C$37) -> 0.4 | L24: =IF(L$20<Toimenpiteet!$C$37,Toimenpiteet!$C$35*100/Toimenpiteet!$C$37*L$20,Toimenpiteet!$C$35*100/Toimenpiteet!$C$37*Toimenpiteet!$C$37) -> 0.5 | M24: =IF(M$20<Toimenpiteet!$C$37,Toimenpiteet!$C$35*100/Toimenpiteet!$C$37*M$20,Toimenpiteet!$C$35*100/Toimenpiteet!$C$37*Toimenpiteet!$C$37) -> 0.5 | N24: =IF(N$20<Toimenpiteet!$C$37,Toimenpiteet!$C$35*100/Toimenpiteet!$C$37*N$20,Toimenpiteet!$C$35*100/Toimenpiteet!$C$37*Toimenpiteet!$C$37) -> 0.5 | O24: =IF(O$20<Toimenpiteet!$C$37,Toimenpiteet!$C$35*100/Toimenpiteet!$C$37*O$20,Toimenpiteet!$C$35*100/Toimenpiteet!$C$37*Toimenpiteet!$C$37) -> 0.5 | ... AF24: =IF(AF$20<Toimenpiteet!$C$37,Toimenpiteet!$C$35*100/Toimenpiteet!$C$37*AF$20,Toimenpiteet!$C$35*100/Toimenpiteet!$C$37*Toimenpiteet!$C$37) -> 0.5
B25: Investointikustannus | E25: =ABS(E14-E23) -> 85 | H25: =IF(COUNTIF($H$9:H9,"x")=0,0,_xlfn.XLOOKUP(COUNTIF($H$9:H9,"x"),$H$20:$AF$20,$H$24:$AF$24)) -> 0 | I25: =IF(COUNTIF($H$9:I9,"x")=0,0,_xlfn.XLOOKUP(COUNTIF($H$9:I9,"x"),$H$20:$AF$20,$H$24:$AF$24)) -> 0.1 | J25: =IF(COUNTIF($H$9:J9,"x")=0,0,_xlfn.XLOOKUP(COUNTIF($H$9:J9,"x"),$H$20:$AF$20,$H$24:$AF$24)) -> 0.2 | K25: =IF(COUNTIF($H$9:K9,"x")=0,0,_xlfn.XLOOKUP(COUNTIF($H$9:K9,"x"),$H$20:$AF$20,$H$24:$AF$24)) -> 0.3 | L25: =IF(COUNTIF($H$9:L9,"x")=0,0,_xlfn.XLOOKUP(COUNTIF($H$9:L9,"x"),$H$20:$AF$20,$H$24:$AF$24)) -> 0.4 | M25: =IF(COUNTIF($H$9:M9,"x")=0,0,_xlfn.XLOOKUP(COUNTIF($H$9:M9,"x"),$H$20:$AF$20,$H$24:$AF$24)) -> 0.4 | N25: =IF(COUNTIF($H$9:N9,"x")=0,0,_xlfn.XLOOKUP(COUNTIF($H$9:N9,"x"),$H$20:$AF$20,$H$24:$AF$24)) -> 0.5 | O25: =IF(COUNTIF($H$9:O9,"x")=0,0,_xlfn.XLOOKUP(COUNTIF($H$9:O9,"x"),$H$20:$AF$20,$H$24:$AF$24)) -> 0.5 | ... AF25: =IF(COUNTIF($H$9:AF9,"x")=0,0,_xlfn.XLOOKUP(COUNTIF($H$9:AF9,"x"),$H$20:$AF$20,$H$24:$AF$24)) -> 0.5
G26: Lannanlevitys / Orgaaninen lannoite / Maanparannuskuitu | H26: =IF(H$20<Toimenpiteet!$C$67,Toimenpiteet!$C$65*100/Toimenpiteet!$C$67*H$20,Toimenpiteet!$C$65*100/Toimenpiteet!$C$67*Toimenpiteet!$C$67) -> 0.2 | I26: =IF(I$20<Toimenpiteet!$C$67,Toimenpiteet!$C$65*100/Toimenpiteet!$C$67*I$20,Toimenpiteet!$C$65*100/Toimenpiteet!$C$67*Toimenpiteet!$C$67) -> 0.4 | J26: =IF(J$20<Toimenpiteet!$C$67,Toimenpiteet!$C$65*100/Toimenpiteet!$C$67*J$20,Toimenpiteet!$C$65*100/Toimenpiteet!$C$67*Toimenpiteet!$C$67) -> 0.6 | K26: =IF(K$20<Toimenpiteet!$C$67,Toimenpiteet!$C$65*100/Toimenpiteet!$C$67*K$20,Toimenpiteet!$C$65*100/Toimenpiteet!$C$67*Toimenpiteet!$C$67) -> 0.8 | L26: =IF(L$20<Toimenpiteet!$C$67,Toimenpiteet!$C$65*100/Toimenpiteet!$C$67*L$20,Toimenpiteet!$C$65*100/Toimenpiteet!$C$67*Toimenpiteet!$C$67) -> 1 | M26: =IF(M$20<Toimenpiteet!$C$67,Toimenpiteet!$C$65*100/Toimenpiteet!$C$67*M$20,Toimenpiteet!$C$65*100/Toimenpiteet!$C$67*Toimenpiteet!$C$67) -> 1.2 | N26: =IF(N$20<Toimenpiteet!$C$67,Toimenpiteet!$C$65*100/Toimenpiteet!$C$67*N$20,Toimenpiteet!$C$65*100/Toimenpiteet!$C$67*Toimenpiteet!$C$67) -> 1.4 | O26: =IF(O$20<Toimenpiteet!$C$67,Toimenpiteet!$C$65*100/Toimenpiteet!$C$67*O$20,Toimenpiteet!$C$65*100/Toimenpiteet!$C$67*Toimenpiteet!$C$67) -> 1.6 | ... AF26: =IF(AF$20<Toimenpiteet!$C$67,Toimenpiteet!$C$65*100/Toimenpiteet!$C$67*AF$20,Toimenpiteet!$C$65*100/Toimenpiteet!$C$67*Toimenpiteet!$C$67) -> 2
H27: =IF(COUNTIF($H$10:H10,"x")=0,0,_xlfn.XLOOKUP(COUNTIF($H$10:H10,"x"),$H$20:$AF$20,$H$26:$AF$26)) -> 0 | I27: =IF(COUNTIF($H$10:I10,"x")=0,0,_xlfn.XLOOKUP(COUNTIF($H$10:I10,"x"),$H$20:$AF$20,$H$26:$AF$26)) -> 0 | J27: =IF(COUNTIF($H$10:J10,"x")=0,0,_xlfn.XLOOKUP(COUNTIF($H$10:J10,"x"),$H$20:$AF$20,$H$26:$AF$26)) -> 0 | K27: =IF(COUNTIF($H$10:K10,"x")=0,0,_xlfn.XLOOKUP(COUNTIF($H$10:K10,"x"),$H$20:$AF$20,$H$26:$AF$26)) -> 0 | L27: =IF(COUNTIF($H$10:L10,"x")=0,0,_xlfn.XLOOKUP(COUNTIF($H$10:L10,"x"),$H$20:$AF$20,$H$26:$AF$26)) -> 0 | M27: =IF(COUNTIF($H$10:M10,"x")=0,0,_xlfn.XLOOKUP(COUNTIF($H$10:M10,"x"),$H$20:$AF$20,$H$26:$AF$26)) -> 0 | N27: =IF(COUNTIF($H$10:N10,"x")=0,0,_xlfn.XLOOKUP(COUNTIF($H$10:N10,"x"),$H$20:$AF$20,$H$26:$AF$26)) -> 0 | O27: =IF(COUNTIF($H$10:O10,"x")=0,0,_xlfn.XLOOKUP(COUNTIF($H$10:O10,"x"),$H$20:$AF$20,$H$26:$AF$26)) -> 0 | ... AF27: =IF(COUNTIF($H$10:AF10,"x")=0,0,_xlfn.XLOOKUP(COUNTIF($H$10:AF10,"x"),$H$20:$AF$20,$H$26:$AF$26)) -> 0
B28: Ojitusinvestointi | G28: Viherlannoitus / Maanparannus- ja saneerauskasvit | H28: =IF(H$20<Toimenpiteet!$C$95,Toimenpiteet!$C$93*100/Toimenpiteet!$C$95*H$20,Toimenpiteet!$C$93*100/Toimenpiteet!$C$95*Toimenpiteet!$C$95) -> 0.1 | I28: =IF(I$20<Toimenpiteet!$C$95,Toimenpiteet!$C$93*100/Toimenpiteet!$C$95*I$20,Toimenpiteet!$C$93*100/Toimenpiteet!$C$95*Toimenpiteet!$C$95) -> 0.2 | J28: =IF(J$20<Toimenpiteet!$C$95,Toimenpiteet!$C$93*100/Toimenpiteet!$C$95*J$20,Toimenpiteet!$C$93*100/Toimenpiteet!$C$95*Toimenpiteet!$C$95) -> 0.3 | K28: =IF(K$20<Toimenpiteet!$C$95,Toimenpiteet!$C$93*100/Toimenpiteet!$C$95*K$20,Toimenpiteet!$C$93*100/Toimenpiteet!$C$95*Toimenpiteet!$C$95) -> 0.4 | L28: =IF(L$20<Toimenpiteet!$C$95,Toimenpiteet!$C$93*100/Toimenpiteet!$C$95*L$20,Toimenpiteet!$C$93*100/Toimenpiteet!$C$95*Toimenpiteet!$C$95) -> 0.5 | M28: =IF(M$20<Toimenpiteet!$C$95,Toimenpiteet!$C$93*100/Toimenpiteet!$C$95*M$20,Toimenpiteet!$C$93*100/Toimenpiteet!$C$95*Toimenpiteet!$C$95) -> 0.6 | N28: =IF(N$20<Toimenpiteet!$C$95,Toimenpiteet!$C$93*100/Toimenpiteet!$C$95*N$20,Toimenpiteet!$C$93*100/Toimenpiteet!$C$95*Toimenpiteet!$C$95) -> 0.7 | O28: =IF(O$20<Toimenpiteet!$C$95,Toimenpiteet!$C$93*100/Toimenpiteet!$C$95*O$20,Toimenpiteet!$C$93*100/Toimenpiteet!$C$95*Toimenpiteet!$C$95) -> 0.8 | ... AF28: =IF(AF$20<Toimenpiteet!$C$95,Toimenpiteet!$C$93*100/Toimenpiteet!$C$95*AF$20,Toimenpiteet!$C$93*100/Toimenpiteet!$C$95*Toimenpiteet!$C$95) -> 1
B29: Vaikutus satoon | H29: =IF(COUNTIF($H$11:H11,"x")=0,0,_xlfn.XLOOKUP(COUNTIF($H$11:H11,"x"),$H$20:$AF$20,$H$28:$AF$28)) -> 0.1 | I29: =IF(COUNTIF($H$11:I11,"x")=0,0,_xlfn.XLOOKUP(COUNTIF($H$11:I11,"x"),$H$20:$AF$20,$H$28:$AF$28)) -> 0.1 | J29: =IF(COUNTIF($H$11:J11,"x")=0,0,_xlfn.XLOOKUP(COUNTIF($H$11:J11,"x"),$H$20:$AF$20,$H$28:$AF$28)) -> 0.1 | K29: =IF(COUNTIF($H$11:K11,"x")=0,0,_xlfn.XLOOKUP(COUNTIF($H$11:K11,"x"),$H$20:$AF$20,$H$28:$AF$28)) -> 0.1 | L29: =IF(COUNTIF($H$11:L11,"x")=0,0,_xlfn.XLOOKUP(COUNTIF($H$11:L11,"x"),$H$20:$AF$20,$H$28:$AF$28)) -> 0.1 | M29: =IF(COUNTIF($H$11:M11,"x")=0,0,_xlfn.XLOOKUP(COUNTIF($H$11:M11,"x"),$H$20:$AF$20,$H$28:$AF$28)) -> 0.2 | N29: =IF(COUNTIF($H$11:N11,"x")=0,0,_xlfn.XLOOKUP(COUNTIF($H$11:N11,"x"),$H$20:$AF$20,$H$28:$AF$28)) -> 0.2 | O29: =IF(COUNTIF($H$11:O11,"x")=0,0,_xlfn.XLOOKUP(COUNTIF($H$11:O11,"x"),$H$20:$AF$20,$H$28:$AF$28)) -> 0.2 | ... AF29: =IF(COUNTIF($H$11:AF11,"x")=0,0,_xlfn.XLOOKUP(COUNTIF($H$11:AF11,"x"),$H$20:$AF$20,$H$28:$AF$28)) -> 0.2
B30: Vaikutus satoon | C30: 0.2 | G30: Kokonaisvaikutus | H30: =SUM(H23+H25+H27+H29)/100 -> 0.001 | I30: =SUM(I23+I25+I27+I29)/100 -> 0.008 | J30: =SUM(J23+J25+J27+J29)/100 -> 0.015 | K30: =SUM(K23+K25+K27+K29)/100 -> 0.022 | L30: =SUM(L23+L25+L27+L29)/100 -> 0.029 | M30: =SUM(M23+M25+M27+M29)/100 -> 0.03 | N30: =SUM(N23+N25+N27+N29)/100 -> 0.037 | O30: =SUM(O23+O25+O27+O29)/100 -> 0.037 | ... AF30: =SUM(AF23+AF25+AF27+AF29)/100 -> 0.037
B31: Vaikutus epäonnistumisen todennäköisyyteen | C31: -0.75
G32: Vaikutus epäonnistumisen todennäköisyyteen
C33: Määrä tai muutosprosentti | D33: Hinta | E33: Summa | G33: Kevennetty muokkaus tai suorakylvö | H33: =IF(H$20<Toimenpiteet!$C$10,Toimenpiteet!$C$9*100/Toimenpiteet!$C$10*H$20,Toimenpiteet!$C$9*100/Toimenpiteet!$C$10*Toimenpiteet!$C$10) -> 0 | I33: =IF(I$20<Toimenpiteet!$C$10,Toimenpiteet!$C$9*100/Toimenpiteet!$C$10*I$20,Toimenpiteet!$C$9*100/Toimenpiteet!$C$10*Toimenpiteet!$C$10) -> 0 | J33: =IF(J$20<Toimenpiteet!$C$10,Toimenpiteet!$C$9*100/Toimenpiteet!$C$10*J$20,Toimenpiteet!$C$9*100/Toimenpiteet!$C$10*Toimenpiteet!$C$10) -> 0 | K33: =IF(K$20<Toimenpiteet!$C$10,Toimenpiteet!$C$9*100/Toimenpiteet!$C$10*K$20,Toimenpiteet!$C$9*100/Toimenpiteet!$C$10*Toimenpiteet!$C$10) -> 0 | L33: =IF(L$20<Toimenpiteet!$C$10,Toimenpiteet!$C$9*100/Toimenpiteet!$C$10*L$20,Toimenpiteet!$C$9*100/Toimenpiteet!$C$10*Toimenpiteet!$C$10) -> 0 | M33: =IF(M$20<Toimenpiteet!$C$10,Toimenpiteet!$C$9*100/Toimenpiteet!$C$10*M$20,Toimenpiteet!$C$9*100/Toimenpiteet!$C$10*Toimenpiteet!$C$10) -> 0 | N33: =IF(N$20<Toimenpiteet!$C$10,Toimenpiteet!$C$9*100/Toimenpiteet!$C$10*N$20,Toimenpiteet!$C$9*100/Toimenpiteet!$C$10*Toimenpiteet!$C$10) -> 0 | O33: =IF(O$20<Toimenpiteet!$C$10,Toimenpiteet!$C$9*100/Toimenpiteet!$C$10*O$20,Toimenpiteet!$C$9*100/Toimenpiteet!$C$10*Toimenpiteet!$C$10) -> 0 | ... AF33: =IF(AF$20<Toimenpiteet!$C$10,Toimenpiteet!$C$9*100/Toimenpiteet!$C$10*AF$20,Toimenpiteet!$C$9*100/Toimenpiteet!$C$10*Toimenpiteet!$C$10) -> 0
B34: Tuotot | H34: =IF(COUNTIF($H$8:H8,"x")=0,0,_xlfn.XLOOKUP(COUNTIF($H$8:H8,"x"),$H$20:$AF$20,$H$33:$AF$33)) -> 0 | I34: =IF(COUNTIF($H$8:I8,"x")=0,0,_xlfn.XLOOKUP(COUNTIF($H$8:I8,"x"),$H$20:$AF$20,$H$33:$AF$33)) -> 0 | J34: =IF(COUNTIF($H$8:J8,"x")=0,0,_xlfn.XLOOKUP(COUNTIF($H$8:J8,"x"),$H$20:$AF$20,$H$33:$AF$33)) -> 0 | K34: =IF(COUNTIF($H$8:K8,"x")=0,0,_xlfn.XLOOKUP(COUNTIF($H$8:K8,"x"),$H$20:$AF$20,$H$33:$AF$33)) -> 0 | L34: =IF(COUNTIF($H$8:L8,"x")=0,0,_xlfn.XLOOKUP(COUNTIF($H$8:L8,"x"),$H$20:$AF$20,$H$33:$AF$33)) -> 0 | M34: =IF(COUNTIF($H$8:M8,"x")=0,0,_xlfn.XLOOKUP(COUNTIF($H$8:M8,"x"),$H$20:$AF$20,$H$33:$AF$33)) -> 0 | N34: =IF(COUNTIF($H$8:N8,"x")=0,0,_xlfn.XLOOKUP(COUNTIF($H$8:N8,"x"),$H$20:$AF$20,$H$33:$AF$33)) -> 0 | O34: =IF(COUNTIF($H$8:O8,"x")=0,0,_xlfn.XLOOKUP(COUNTIF($H$8:O8,"x"),$H$20:$AF$20,$H$33:$AF$33)) -> 0 | ... AF34: =IF(COUNTIF($H$8:AF8,"x")=0,0,_xlfn.XLOOKUP(COUNTIF($H$8:AF8,"x"),$H$20:$AF$20,$H$33:$AF$33)) -> 0
B35: Tuki | C35: 0.3 | E35: =C35*E49 -> 600 | G35: Alus- ja kerääjäkasvit | H35: =IF(H$20<Toimenpiteet!$C$37,Toimenpiteet!$C$36*100/Toimenpiteet!$C$37*H$20,Toimenpiteet!$C$36*100/Toimenpiteet!$C$37*Toimenpiteet!$C$37) -> 0 | I35: =IF(I$20<Toimenpiteet!$C$37,Toimenpiteet!$C$36*100/Toimenpiteet!$C$37*I$20,Toimenpiteet!$C$36*100/Toimenpiteet!$C$37*Toimenpiteet!$C$37) -> 0 | J35: =IF(J$20<Toimenpiteet!$C$37,Toimenpiteet!$C$36*100/Toimenpiteet!$C$37*J$20,Toimenpiteet!$C$36*100/Toimenpiteet!$C$37*Toimenpiteet!$C$37) -> 0 | K35: =IF(K$20<Toimenpiteet!$C$37,Toimenpiteet!$C$36*100/Toimenpiteet!$C$37*K$20,Toimenpiteet!$C$36*100/Toimenpiteet!$C$37*Toimenpiteet!$C$37) -> 0 | L35: =IF(L$20<Toimenpiteet!$C$37,Toimenpiteet!$C$36*100/Toimenpiteet!$C$37*L$20,Toimenpiteet!$C$36*100/Toimenpiteet!$C$37*Toimenpiteet!$C$37) -> 0 | M35: =IF(M$20<Toimenpiteet!$C$37,Toimenpiteet!$C$36*100/Toimenpiteet!$C$37*M$20,Toimenpiteet!$C$36*100/Toimenpiteet!$C$37*Toimenpiteet!$C$37) -> 0 | N35: =IF(N$20<Toimenpiteet!$C$37,Toimenpiteet!$C$36*100/Toimenpiteet!$C$37*N$20,Toimenpiteet!$C$36*100/Toimenpiteet!$C$37*Toimenpiteet!$C$37) -> 0 | O35: =IF(O$20<Toimenpiteet!$C$37,Toimenpiteet!$C$36*100/Toimenpiteet!$C$37*O$20,Toimenpiteet!$C$36*100/Toimenpiteet!$C$37*Toimenpiteet!$C$37) -> 0 | ... AF35: =IF(AF$20<Toimenpiteet!$C$37,Toimenpiteet!$C$36*100/Toimenpiteet!$C$37*AF$20,Toimenpiteet!$C$36*100/Toimenpiteet!$C$37*Toimenpiteet!$C$37) -> 0
H36: =IF(COUNTIF($H$9:H9,"x")=0,0,_xlfn.XLOOKUP(COUNTIF($H$9:H9,"x"),$H$20:$AF$20,$H$35:$AF$35)) -> 0 | I36: =IF(COUNTIF($H$9:I9,"x")=0,0,_xlfn.XLOOKUP(COUNTIF($H$9:I9,"x"),$H$20:$AF$20,$H$35:$AF$35)) -> 0 | J36: =IF(COUNTIF($H$9:J9,"x")=0,0,_xlfn.XLOOKUP(COUNTIF($H$9:J9,"x"),$H$20:$AF$20,$H$35:$AF$35)) -> 0 | K36: =IF(COUNTIF($H$9:K9,"x")=0,0,_xlfn.XLOOKUP(COUNTIF($H$9:K9,"x"),$H$20:$AF$20,$H$35:$AF$35)) -> 0 | L36: =IF(COUNTIF($H$9:L9,"x")=0,0,_xlfn.XLOOKUP(COUNTIF($H$9:L9,"x"),$H$20:$AF$20,$H$35:$AF$35)) -> 0 | M36: =IF(COUNTIF($H$9:M9,"x")=0,0,_xlfn.XLOOKUP(COUNTIF($H$9:M9,"x"),$H$20:$AF$20,$H$35:$AF$35)) -> 0 | N36: =IF(COUNTIF($H$9:N9,"x")=0,0,_xlfn.XLOOKUP(COUNTIF($H$9:N9,"x"),$H$20:$AF$20,$H$35:$AF$35)) -> 0 | O36: =IF(COUNTIF($H$9:O9,"x")=0,0,_xlfn.XLOOKUP(COUNTIF($H$9:O9,"x"),$H$20:$AF$20,$H$35:$AF$35)) -> 0 | ... AF36: =IF(COUNTIF($H$9:AF9,"x")=0,0,_xlfn.XLOOKUP(COUNTIF($H$9:AF9,"x"),$H$20:$AF$20,$H$35:$AF$35)) -> 0
